[2021-06-14 12:48:59,868] {taskinstance.py:876} INFO - Dependencies all met for <TaskInstance: summary_db.ambassador_mishaps 2021-06-13T00:00:00+00:00 [queued]>
[2021-06-14 12:49:00,226] {taskinstance.py:876} INFO - Dependencies all met for <TaskInstance: summary_db.ambassador_mishaps 2021-06-13T00:00:00+00:00 [queued]>
[2021-06-14 12:49:00,227] {taskinstance.py:1067} INFO - 
--------------------------------------------------------------------------------
[2021-06-14 12:49:00,227] {taskinstance.py:1068} INFO - Starting attempt 1 of 2
[2021-06-14 12:49:00,227] {taskinstance.py:1069} INFO - 
--------------------------------------------------------------------------------
[2021-06-14 12:49:00,340] {taskinstance.py:1087} INFO - Executing <Task(PythonOperator): ambassador_mishaps> on 2021-06-13T00:00:00+00:00
[2021-06-14 12:49:00,757] {standard_task_runner.py:52} INFO - Started process 381 to run task
[2021-06-14 12:49:00,868] {standard_task_runner.py:76} INFO - Running: ['***', 'tasks', 'run', 'summary_db', 'ambassador_mishaps', '2021-06-13T00:00:00+00:00', '--job-id', '41', '--pool', 'default_pool', '--raw', '--subdir', 'DAGS_FOLDER/first_dag.py', '--cfg-path', '/tmp/tmp22ln3bf6', '--error-file', '/tmp/tmp6xj3i9ss']
[2021-06-14 12:49:00,869] {standard_task_runner.py:77} INFO - Job 41: Subtask ambassador_mishaps
[2021-06-14 12:49:01,579] {logging_mixin.py:104} INFO - Running <TaskInstance: summary_db.ambassador_mishaps 2021-06-13T00:00:00+00:00 [running]> on host 7874826b9cd7
[2021-06-14 12:49:02,177] {taskinstance.py:1282} INFO - Exporting the following env vars:
AIRFLOW_CTX_DAG_OWNER=***
AIRFLOW_CTX_DAG_ID=summary_db
AIRFLOW_CTX_TASK_ID=ambassador_mishaps
AIRFLOW_CTX_EXECUTION_DATE=2021-06-13T00:00:00+00:00
AIRFLOW_CTX_DAG_RUN_ID=scheduled__2021-06-13T00:00:00+00:00
[2021-06-14 12:49:02,178] {logging_mixin.py:104} INFO - ------------------------------------Inside Function-----------------------------
[2021-06-14 12:49:06,810] {logging_mixin.py:104} INFO - -------------------------------Data read into dataframe---------------------------
[2021-06-14 12:49:07,258] {taskinstance.py:1481} ERROR - Task failed with exception
Traceback (most recent call last):
  File "/home/airflow/.local/lib/python3.6/site-packages/airflow/models/taskinstance.py", line 1137, in _run_raw_task
    self._prepare_and_execute_task_with_callbacks(context, task)
  File "/home/airflow/.local/lib/python3.6/site-packages/airflow/models/taskinstance.py", line 1311, in _prepare_and_execute_task_with_callbacks
    result = self._execute_task(context, task_copy)
  File "/home/airflow/.local/lib/python3.6/site-packages/airflow/models/taskinstance.py", line 1341, in _execute_task
    result = task_copy.execute(context=context)
  File "/home/airflow/.local/lib/python3.6/site-packages/airflow/operators/python.py", line 150, in execute
    return_value = self.execute_callable()
  File "/home/airflow/.local/lib/python3.6/site-packages/airflow/operators/python.py", line 161, in execute_callable
    return self.python_callable(*self.op_args, **self.op_kwargs)
  File "/opt/airflow/dags/first_dag.py", line 144, in ambassador_mishaps
    index=False)
  File "/home/airflow/.local/lib/python3.6/site-packages/pandas/core/generic.py", line 2615, in to_sql
    method=method,
  File "/home/airflow/.local/lib/python3.6/site-packages/pandas/io/sql.py", line 598, in to_sql
    method=method,
  File "/home/airflow/.local/lib/python3.6/site-packages/pandas/io/sql.py", line 1393, in to_sql
    table.create()
  File "/home/airflow/.local/lib/python3.6/site-packages/pandas/io/sql.py", line 725, in create
    self.pd_sql.drop_table(self.name, self.schema)
  File "/home/airflow/.local/lib/python3.6/site-packages/pandas/io/sql.py", line 1453, in drop_table
    self.meta.reflect(only=[table_name], schema=schema)
  File "/home/airflow/.local/lib/python3.6/site-packages/sqlalchemy/sql/schema.py", line 4612, in reflect
    "in %r%s: (%s)" % (bind.engine, s, ", ".join(missing))
sqlalchemy.exc.InvalidRequestError: Could not reflect: requested table(s) not available in Engine(mysql://root:***@host.docker.internal:3306/21north) schema '21north': (21N_ambassador_mishaps)
[2021-06-14 12:49:07,273] {taskinstance.py:1531} INFO - Marking task as UP_FOR_RETRY. dag_id=summary_db, task_id=ambassador_mishaps, execution_date=20210613T000000, start_date=20210614T124859, end_date=20210614T124907
[2021-06-14 12:49:07,446] {local_task_job.py:151} INFO - Task exited with return code 1
[2021-06-14 15:28:06,642] {taskinstance.py:876} INFO - Dependencies all met for <TaskInstance: summary_db.ambassador_mishaps 2021-06-13T00:00:00+00:00 [queued]>
[2021-06-14 15:28:07,022] {taskinstance.py:876} INFO - Dependencies all met for <TaskInstance: summary_db.ambassador_mishaps 2021-06-13T00:00:00+00:00 [queued]>
[2021-06-14 15:28:07,022] {taskinstance.py:1067} INFO - 
--------------------------------------------------------------------------------
[2021-06-14 15:28:07,022] {taskinstance.py:1068} INFO - Starting attempt 1 of 2
[2021-06-14 15:28:07,023] {taskinstance.py:1069} INFO - 
--------------------------------------------------------------------------------
[2021-06-14 15:28:07,137] {taskinstance.py:1087} INFO - Executing <Task(PythonOperator): ambassador_mishaps> on 2021-06-13T00:00:00+00:00
[2021-06-14 15:28:07,393] {standard_task_runner.py:52} INFO - Started process 797 to run task
[2021-06-14 15:28:07,508] {standard_task_runner.py:76} INFO - Running: ['***', 'tasks', 'run', 'summary_db', 'ambassador_mishaps', '2021-06-13T00:00:00+00:00', '--job-id', '76', '--pool', 'default_pool', '--raw', '--subdir', 'DAGS_FOLDER/first_dag.py', '--cfg-path', '/tmp/tmpsd371vve', '--error-file', '/tmp/tmpxq6wc_06']
[2021-06-14 15:28:07,589] {standard_task_runner.py:77} INFO - Job 76: Subtask ambassador_mishaps
[2021-06-14 15:28:08,370] {logging_mixin.py:104} INFO - Running <TaskInstance: summary_db.ambassador_mishaps 2021-06-13T00:00:00+00:00 [running]> on host 7874826b9cd7
[2021-06-14 15:28:09,334] {taskinstance.py:1282} INFO - Exporting the following env vars:
AIRFLOW_CTX_DAG_OWNER=***
AIRFLOW_CTX_DAG_ID=summary_db
AIRFLOW_CTX_TASK_ID=ambassador_mishaps
AIRFLOW_CTX_EXECUTION_DATE=2021-06-13T00:00:00+00:00
AIRFLOW_CTX_DAG_RUN_ID=scheduled__2021-06-13T00:00:00+00:00
[2021-06-14 15:28:09,335] {logging_mixin.py:104} INFO - ------------------------------------Inside Function-----------------------------
[2021-06-14 15:28:14,796] {logging_mixin.py:104} INFO - -------------------------------Data read into dataframe---------------------------
[2021-06-14 15:28:15,380] {taskinstance.py:1481} ERROR - Task failed with exception
Traceback (most recent call last):
  File "/home/airflow/.local/lib/python3.6/site-packages/airflow/models/taskinstance.py", line 1137, in _run_raw_task
    self._prepare_and_execute_task_with_callbacks(context, task)
  File "/home/airflow/.local/lib/python3.6/site-packages/airflow/models/taskinstance.py", line 1311, in _prepare_and_execute_task_with_callbacks
    result = self._execute_task(context, task_copy)
  File "/home/airflow/.local/lib/python3.6/site-packages/airflow/models/taskinstance.py", line 1341, in _execute_task
    result = task_copy.execute(context=context)
  File "/home/airflow/.local/lib/python3.6/site-packages/airflow/operators/python.py", line 150, in execute
    return_value = self.execute_callable()
  File "/home/airflow/.local/lib/python3.6/site-packages/airflow/operators/python.py", line 161, in execute_callable
    return self.python_callable(*self.op_args, **self.op_kwargs)
  File "/opt/airflow/dags/first_dag.py", line 146, in ambassador_mishaps
    index=False)
  File "/home/airflow/.local/lib/python3.6/site-packages/pandas/core/generic.py", line 2615, in to_sql
    method=method,
  File "/home/airflow/.local/lib/python3.6/site-packages/pandas/io/sql.py", line 598, in to_sql
    method=method,
  File "/home/airflow/.local/lib/python3.6/site-packages/pandas/io/sql.py", line 1393, in to_sql
    table.create()
  File "/home/airflow/.local/lib/python3.6/site-packages/pandas/io/sql.py", line 725, in create
    self.pd_sql.drop_table(self.name, self.schema)
  File "/home/airflow/.local/lib/python3.6/site-packages/pandas/io/sql.py", line 1453, in drop_table
    self.meta.reflect(only=[table_name], schema=schema)
  File "/home/airflow/.local/lib/python3.6/site-packages/sqlalchemy/sql/schema.py", line 4612, in reflect
    "in %r%s: (%s)" % (bind.engine, s, ", ".join(missing))
sqlalchemy.exc.InvalidRequestError: Could not reflect: requested table(s) not available in Engine(mysql://root:***@host.docker.internal:3306/21north) schema '21north': (21N_ambassador_mishaps)
[2021-06-14 15:28:15,418] {taskinstance.py:1531} INFO - Marking task as UP_FOR_RETRY. dag_id=summary_db, task_id=ambassador_mishaps, execution_date=20210613T000000, start_date=20210614T152806, end_date=20210614T152815
[2021-06-14 15:28:15,914] {local_task_job.py:151} INFO - Task exited with return code 1
[2021-06-14 18:33:53,289] {taskinstance.py:876} INFO - Dependencies all met for <TaskInstance: summary_db.ambassador_mishaps 2021-06-13T00:00:00+00:00 [queued]>
[2021-06-14 18:33:53,936] {taskinstance.py:876} INFO - Dependencies all met for <TaskInstance: summary_db.ambassador_mishaps 2021-06-13T00:00:00+00:00 [queued]>
[2021-06-14 18:33:53,937] {taskinstance.py:1067} INFO - 
--------------------------------------------------------------------------------
[2021-06-14 18:33:53,937] {taskinstance.py:1068} INFO - Starting attempt 1 of 2
[2021-06-14 18:33:53,937] {taskinstance.py:1069} INFO - 
--------------------------------------------------------------------------------
[2021-06-14 18:33:54,074] {taskinstance.py:1087} INFO - Executing <Task(PythonOperator): ambassador_mishaps> on 2021-06-13T00:00:00+00:00
[2021-06-14 18:33:54,221] {standard_task_runner.py:52} INFO - Started process 251 to run task
[2021-06-14 18:33:54,749] {standard_task_runner.py:76} INFO - Running: ['***', 'tasks', 'run', 'summary_db', 'ambassador_mishaps', '2021-06-13T00:00:00+00:00', '--job-id', '104', '--pool', 'default_pool', '--raw', '--subdir', 'DAGS_FOLDER/first_dag.py', '--cfg-path', '/tmp/tmpndwck1hf', '--error-file', '/tmp/tmp3tv6glp6']
[2021-06-14 18:33:54,776] {standard_task_runner.py:77} INFO - Job 104: Subtask ambassador_mishaps
[2021-06-14 18:33:56,387] {logging_mixin.py:104} INFO - Running <TaskInstance: summary_db.ambassador_mishaps 2021-06-13T00:00:00+00:00 [running]> on host 89c270a4555f
[2021-06-14 18:33:58,003] {taskinstance.py:1282} INFO - Exporting the following env vars:
AIRFLOW_CTX_DAG_OWNER=***
AIRFLOW_CTX_DAG_ID=summary_db
AIRFLOW_CTX_TASK_ID=ambassador_mishaps
AIRFLOW_CTX_EXECUTION_DATE=2021-06-13T00:00:00+00:00
AIRFLOW_CTX_DAG_RUN_ID=scheduled__2021-06-13T00:00:00+00:00
[2021-06-14 18:33:58,007] {logging_mixin.py:104} INFO - ------------------------------------Inside Function-----------------------------
[2021-06-14 18:34:12,956] {logging_mixin.py:104} INFO - -------------------------------Data read into dataframe---------------------------
[2021-06-14 18:34:23,528] {logging_mixin.py:104} INFO - ----------------------------------Data written into summary DB----------------------
[2021-06-14 18:34:23,529] {python.py:151} INFO - Done. Returned value was: None
[2021-06-14 18:34:23,726] {taskinstance.py:1191} INFO - Marking task as SUCCESS. dag_id=summary_db, task_id=ambassador_mishaps, execution_date=20210613T000000, start_date=20210614T183353, end_date=20210614T183423
[2021-06-14 18:34:24,192] {taskinstance.py:1245} INFO - 0 downstream tasks scheduled from follow-on schedule check
[2021-06-14 18:34:24,368] {local_task_job.py:151} INFO - Task exited with return code 0
