[2021-06-14 12:54:12,151] {taskinstance.py:876} INFO - Dependencies all met for <TaskInstance: summary_db.ambassador_mishaps 2021-06-13T00:00:00+00:00 [queued]>
[2021-06-14 12:54:12,307] {taskinstance.py:876} INFO - Dependencies all met for <TaskInstance: summary_db.ambassador_mishaps 2021-06-13T00:00:00+00:00 [queued]>
[2021-06-14 12:54:12,313] {taskinstance.py:1067} INFO - 
--------------------------------------------------------------------------------
[2021-06-14 12:54:12,313] {taskinstance.py:1068} INFO - Starting attempt 2 of 2
[2021-06-14 12:54:12,314] {taskinstance.py:1069} INFO - 
--------------------------------------------------------------------------------
[2021-06-14 12:54:12,516] {taskinstance.py:1087} INFO - Executing <Task(PythonOperator): ambassador_mishaps> on 2021-06-13T00:00:00+00:00
[2021-06-14 12:54:12,567] {standard_task_runner.py:52} INFO - Started process 669 to run task
[2021-06-14 12:54:12,596] {standard_task_runner.py:76} INFO - Running: ['***', 'tasks', 'run', 'summary_db', 'ambassador_mishaps', '2021-06-13T00:00:00+00:00', '--job-id', '62', '--pool', 'default_pool', '--raw', '--subdir', 'DAGS_FOLDER/first_dag.py', '--cfg-path', '/tmp/tmppwf71kis', '--error-file', '/tmp/tmphu3e4m1b']
[2021-06-14 12:54:12,608] {standard_task_runner.py:77} INFO - Job 62: Subtask ambassador_mishaps
[2021-06-14 12:54:13,017] {logging_mixin.py:104} INFO - Running <TaskInstance: summary_db.ambassador_mishaps 2021-06-13T00:00:00+00:00 [running]> on host 7874826b9cd7
[2021-06-14 12:54:13,416] {taskinstance.py:1282} INFO - Exporting the following env vars:
AIRFLOW_CTX_DAG_OWNER=***
AIRFLOW_CTX_DAG_ID=summary_db
AIRFLOW_CTX_TASK_ID=ambassador_mishaps
AIRFLOW_CTX_EXECUTION_DATE=2021-06-13T00:00:00+00:00
AIRFLOW_CTX_DAG_RUN_ID=scheduled__2021-06-13T00:00:00+00:00
[2021-06-14 12:54:13,418] {logging_mixin.py:104} INFO - ------------------------------------Inside Function-----------------------------
[2021-06-14 12:54:15,864] {logging_mixin.py:104} INFO - -------------------------------Data read into dataframe---------------------------
[2021-06-14 12:54:16,002] {taskinstance.py:1481} ERROR - Task failed with exception
Traceback (most recent call last):
  File "/home/airflow/.local/lib/python3.6/site-packages/airflow/models/taskinstance.py", line 1137, in _run_raw_task
    self._prepare_and_execute_task_with_callbacks(context, task)
  File "/home/airflow/.local/lib/python3.6/site-packages/airflow/models/taskinstance.py", line 1311, in _prepare_and_execute_task_with_callbacks
    result = self._execute_task(context, task_copy)
  File "/home/airflow/.local/lib/python3.6/site-packages/airflow/models/taskinstance.py", line 1341, in _execute_task
    result = task_copy.execute(context=context)
  File "/home/airflow/.local/lib/python3.6/site-packages/airflow/operators/python.py", line 150, in execute
    return_value = self.execute_callable()
  File "/home/airflow/.local/lib/python3.6/site-packages/airflow/operators/python.py", line 161, in execute_callable
    return self.python_callable(*self.op_args, **self.op_kwargs)
  File "/opt/airflow/dags/first_dag.py", line 144, in ambassador_mishaps
    index=False)
  File "/home/airflow/.local/lib/python3.6/site-packages/pandas/core/generic.py", line 2615, in to_sql
    method=method,
  File "/home/airflow/.local/lib/python3.6/site-packages/pandas/io/sql.py", line 598, in to_sql
    method=method,
  File "/home/airflow/.local/lib/python3.6/site-packages/pandas/io/sql.py", line 1393, in to_sql
    table.create()
  File "/home/airflow/.local/lib/python3.6/site-packages/pandas/io/sql.py", line 725, in create
    self.pd_sql.drop_table(self.name, self.schema)
  File "/home/airflow/.local/lib/python3.6/site-packages/pandas/io/sql.py", line 1453, in drop_table
    self.meta.reflect(only=[table_name], schema=schema)
  File "/home/airflow/.local/lib/python3.6/site-packages/sqlalchemy/sql/schema.py", line 4612, in reflect
    "in %r%s: (%s)" % (bind.engine, s, ", ".join(missing))
sqlalchemy.exc.InvalidRequestError: Could not reflect: requested table(s) not available in Engine(mysql://root:***@host.docker.internal:3306/21north) schema '21north': (21N_ambassador_mishaps)
[2021-06-14 12:54:16,014] {taskinstance.py:1531} INFO - Marking task as FAILED. dag_id=summary_db, task_id=ambassador_mishaps, execution_date=20210613T000000, start_date=20210614T125412, end_date=20210614T125416
[2021-06-14 12:54:16,105] {local_task_job.py:151} INFO - Task exited with return code 1
[2021-06-14 15:33:17,437] {taskinstance.py:876} INFO - Dependencies all met for <TaskInstance: summary_db.ambassador_mishaps 2021-06-13T00:00:00+00:00 [queued]>
[2021-06-14 15:33:17,487] {taskinstance.py:876} INFO - Dependencies all met for <TaskInstance: summary_db.ambassador_mishaps 2021-06-13T00:00:00+00:00 [queued]>
[2021-06-14 15:33:17,488] {taskinstance.py:1067} INFO - 
--------------------------------------------------------------------------------
[2021-06-14 15:33:17,488] {taskinstance.py:1068} INFO - Starting attempt 2 of 2
[2021-06-14 15:33:17,488] {taskinstance.py:1069} INFO - 
--------------------------------------------------------------------------------
[2021-06-14 15:33:17,512] {taskinstance.py:1087} INFO - Executing <Task(PythonOperator): ambassador_mishaps> on 2021-06-13T00:00:00+00:00
[2021-06-14 15:33:17,523] {standard_task_runner.py:52} INFO - Started process 1071 to run task
[2021-06-14 15:33:17,540] {standard_task_runner.py:76} INFO - Running: ['***', 'tasks', 'run', 'summary_db', 'ambassador_mishaps', '2021-06-13T00:00:00+00:00', '--job-id', '98', '--pool', 'default_pool', '--raw', '--subdir', 'DAGS_FOLDER/first_dag.py', '--cfg-path', '/tmp/tmpi9q45bi2', '--error-file', '/tmp/tmp54bksj24']
[2021-06-14 15:33:17,541] {standard_task_runner.py:77} INFO - Job 98: Subtask ambassador_mishaps
[2021-06-14 15:33:17,618] {logging_mixin.py:104} INFO - Running <TaskInstance: summary_db.ambassador_mishaps 2021-06-13T00:00:00+00:00 [running]> on host 7874826b9cd7
[2021-06-14 15:33:17,720] {taskinstance.py:1282} INFO - Exporting the following env vars:
AIRFLOW_CTX_DAG_OWNER=***
AIRFLOW_CTX_DAG_ID=summary_db
AIRFLOW_CTX_TASK_ID=ambassador_mishaps
AIRFLOW_CTX_EXECUTION_DATE=2021-06-13T00:00:00+00:00
AIRFLOW_CTX_DAG_RUN_ID=scheduled__2021-06-13T00:00:00+00:00
[2021-06-14 15:33:17,724] {logging_mixin.py:104} INFO - ------------------------------------Inside Function-----------------------------
[2021-06-14 15:33:20,958] {logging_mixin.py:104} INFO - -------------------------------Data read into dataframe---------------------------
[2021-06-14 15:33:21,422] {taskinstance.py:1481} ERROR - Task failed with exception
Traceback (most recent call last):
  File "/home/airflow/.local/lib/python3.6/site-packages/airflow/models/taskinstance.py", line 1137, in _run_raw_task
    self._prepare_and_execute_task_with_callbacks(context, task)
  File "/home/airflow/.local/lib/python3.6/site-packages/airflow/models/taskinstance.py", line 1311, in _prepare_and_execute_task_with_callbacks
    result = self._execute_task(context, task_copy)
  File "/home/airflow/.local/lib/python3.6/site-packages/airflow/models/taskinstance.py", line 1341, in _execute_task
    result = task_copy.execute(context=context)
  File "/home/airflow/.local/lib/python3.6/site-packages/airflow/operators/python.py", line 150, in execute
    return_value = self.execute_callable()
  File "/home/airflow/.local/lib/python3.6/site-packages/airflow/operators/python.py", line 161, in execute_callable
    return self.python_callable(*self.op_args, **self.op_kwargs)
  File "/opt/airflow/dags/first_dag.py", line 146, in ambassador_mishaps
    index=False)
  File "/home/airflow/.local/lib/python3.6/site-packages/pandas/core/generic.py", line 2615, in to_sql
    method=method,
  File "/home/airflow/.local/lib/python3.6/site-packages/pandas/io/sql.py", line 598, in to_sql
    method=method,
  File "/home/airflow/.local/lib/python3.6/site-packages/pandas/io/sql.py", line 1393, in to_sql
    table.create()
  File "/home/airflow/.local/lib/python3.6/site-packages/pandas/io/sql.py", line 725, in create
    self.pd_sql.drop_table(self.name, self.schema)
  File "/home/airflow/.local/lib/python3.6/site-packages/pandas/io/sql.py", line 1453, in drop_table
    self.meta.reflect(only=[table_name], schema=schema)
  File "/home/airflow/.local/lib/python3.6/site-packages/sqlalchemy/sql/schema.py", line 4612, in reflect
    "in %r%s: (%s)" % (bind.engine, s, ", ".join(missing))
sqlalchemy.exc.InvalidRequestError: Could not reflect: requested table(s) not available in Engine(mysql://root:***@host.docker.internal:3306/21north) schema '21north': (21N_ambassador_mishaps)
[2021-06-14 15:33:21,445] {taskinstance.py:1531} INFO - Marking task as FAILED. dag_id=summary_db, task_id=ambassador_mishaps, execution_date=20210613T000000, start_date=20210614T153317, end_date=20210614T153321
[2021-06-14 15:33:21,546] {local_task_job.py:151} INFO - Task exited with return code 1
