[2021-06-14 12:48:59,606] {taskinstance.py:876} INFO - Dependencies all met for <TaskInstance: summary_db.ambassador_refunds_type 2021-06-13T00:00:00+00:00 [queued]>
[2021-06-14 12:48:59,909] {taskinstance.py:876} INFO - Dependencies all met for <TaskInstance: summary_db.ambassador_refunds_type 2021-06-13T00:00:00+00:00 [queued]>
[2021-06-14 12:48:59,912] {taskinstance.py:1067} INFO - 
--------------------------------------------------------------------------------
[2021-06-14 12:48:59,914] {taskinstance.py:1068} INFO - Starting attempt 1 of 2
[2021-06-14 12:48:59,919] {taskinstance.py:1069} INFO - 
--------------------------------------------------------------------------------
[2021-06-14 12:49:00,194] {taskinstance.py:1087} INFO - Executing <Task(PythonOperator): ambassador_refunds_type> on 2021-06-13T00:00:00+00:00
[2021-06-14 12:49:00,219] {standard_task_runner.py:52} INFO - Started process 371 to run task
[2021-06-14 12:49:00,305] {standard_task_runner.py:76} INFO - Running: ['***', 'tasks', 'run', 'summary_db', 'ambassador_refunds_type', '2021-06-13T00:00:00+00:00', '--job-id', '36', '--pool', 'default_pool', '--raw', '--subdir', 'DAGS_FOLDER/first_dag.py', '--cfg-path', '/tmp/tmpzqqoxa00', '--error-file', '/tmp/tmpk37pe_iu']
[2021-06-14 12:49:00,309] {standard_task_runner.py:77} INFO - Job 36: Subtask ambassador_refunds_type
[2021-06-14 12:49:01,470] {logging_mixin.py:104} INFO - Running <TaskInstance: summary_db.ambassador_refunds_type 2021-06-13T00:00:00+00:00 [running]> on host 7874826b9cd7
[2021-06-14 12:49:02,357] {taskinstance.py:1282} INFO - Exporting the following env vars:
AIRFLOW_CTX_DAG_OWNER=***
AIRFLOW_CTX_DAG_ID=summary_db
AIRFLOW_CTX_TASK_ID=ambassador_refunds_type
AIRFLOW_CTX_EXECUTION_DATE=2021-06-13T00:00:00+00:00
AIRFLOW_CTX_DAG_RUN_ID=scheduled__2021-06-13T00:00:00+00:00
[2021-06-14 12:49:02,359] {logging_mixin.py:104} INFO - ------------------------------------Inside Function-----------------------------
[2021-06-14 12:49:04,311] {logging_mixin.py:104} INFO - -------------------------------Data read into dataframe---------------------------
[2021-06-14 12:49:04,505] {taskinstance.py:1481} ERROR - Task failed with exception
Traceback (most recent call last):
  File "/home/airflow/.local/lib/python3.6/site-packages/airflow/models/taskinstance.py", line 1137, in _run_raw_task
    self._prepare_and_execute_task_with_callbacks(context, task)
  File "/home/airflow/.local/lib/python3.6/site-packages/airflow/models/taskinstance.py", line 1311, in _prepare_and_execute_task_with_callbacks
    result = self._execute_task(context, task_copy)
  File "/home/airflow/.local/lib/python3.6/site-packages/airflow/models/taskinstance.py", line 1341, in _execute_task
    result = task_copy.execute(context=context)
  File "/home/airflow/.local/lib/python3.6/site-packages/airflow/operators/python.py", line 150, in execute
    return_value = self.execute_callable()
  File "/home/airflow/.local/lib/python3.6/site-packages/airflow/operators/python.py", line 161, in execute_callable
    return self.python_callable(*self.op_args, **self.op_kwargs)
  File "/opt/airflow/dags/first_dag.py", line 181, in ambassador_refunds_type
    index=False)
  File "/home/airflow/.local/lib/python3.6/site-packages/pandas/core/generic.py", line 2615, in to_sql
    method=method,
  File "/home/airflow/.local/lib/python3.6/site-packages/pandas/io/sql.py", line 598, in to_sql
    method=method,
  File "/home/airflow/.local/lib/python3.6/site-packages/pandas/io/sql.py", line 1393, in to_sql
    table.create()
  File "/home/airflow/.local/lib/python3.6/site-packages/pandas/io/sql.py", line 725, in create
    self.pd_sql.drop_table(self.name, self.schema)
  File "/home/airflow/.local/lib/python3.6/site-packages/pandas/io/sql.py", line 1453, in drop_table
    self.meta.reflect(only=[table_name], schema=schema)
  File "/home/airflow/.local/lib/python3.6/site-packages/sqlalchemy/sql/schema.py", line 4612, in reflect
    "in %r%s: (%s)" % (bind.engine, s, ", ".join(missing))
sqlalchemy.exc.InvalidRequestError: Could not reflect: requested table(s) not available in Engine(mysql://root:***@host.docker.internal:3306/21north) schema '21north': (21N_ambassador_refunds_type)
[2021-06-14 12:49:04,516] {taskinstance.py:1531} INFO - Marking task as UP_FOR_RETRY. dag_id=summary_db, task_id=ambassador_refunds_type, execution_date=20210613T000000, start_date=20210614T124859, end_date=20210614T124904
[2021-06-14 12:49:04,620] {local_task_job.py:151} INFO - Task exited with return code 1
[2021-06-14 15:28:06,261] {taskinstance.py:876} INFO - Dependencies all met for <TaskInstance: summary_db.ambassador_refunds_type 2021-06-13T00:00:00+00:00 [queued]>
[2021-06-14 15:28:06,687] {taskinstance.py:876} INFO - Dependencies all met for <TaskInstance: summary_db.ambassador_refunds_type 2021-06-13T00:00:00+00:00 [queued]>
[2021-06-14 15:28:06,687] {taskinstance.py:1067} INFO - 
--------------------------------------------------------------------------------
[2021-06-14 15:28:06,687] {taskinstance.py:1068} INFO - Starting attempt 1 of 2
[2021-06-14 15:28:06,687] {taskinstance.py:1069} INFO - 
--------------------------------------------------------------------------------
[2021-06-14 15:28:06,808] {taskinstance.py:1087} INFO - Executing <Task(PythonOperator): ambassador_refunds_type> on 2021-06-13T00:00:00+00:00
[2021-06-14 15:28:06,964] {standard_task_runner.py:52} INFO - Started process 794 to run task
[2021-06-14 15:28:07,030] {standard_task_runner.py:76} INFO - Running: ['***', 'tasks', 'run', 'summary_db', 'ambassador_refunds_type', '2021-06-13T00:00:00+00:00', '--job-id', '75', '--pool', 'default_pool', '--raw', '--subdir', 'DAGS_FOLDER/first_dag.py', '--cfg-path', '/tmp/tmponse6noo', '--error-file', '/tmp/tmppvr2evsl']
[2021-06-14 15:28:07,032] {standard_task_runner.py:77} INFO - Job 75: Subtask ambassador_refunds_type
[2021-06-14 15:28:07,870] {logging_mixin.py:104} INFO - Running <TaskInstance: summary_db.ambassador_refunds_type 2021-06-13T00:00:00+00:00 [running]> on host 7874826b9cd7
[2021-06-14 15:28:08,960] {taskinstance.py:1282} INFO - Exporting the following env vars:
AIRFLOW_CTX_DAG_OWNER=***
AIRFLOW_CTX_DAG_ID=summary_db
AIRFLOW_CTX_TASK_ID=ambassador_refunds_type
AIRFLOW_CTX_EXECUTION_DATE=2021-06-13T00:00:00+00:00
AIRFLOW_CTX_DAG_RUN_ID=scheduled__2021-06-13T00:00:00+00:00
[2021-06-14 15:28:08,961] {logging_mixin.py:104} INFO - ------------------------------------Inside Function-----------------------------
[2021-06-14 15:28:11,306] {logging_mixin.py:104} INFO - -------------------------------Data read into dataframe---------------------------
[2021-06-14 15:28:11,554] {taskinstance.py:1481} ERROR - Task failed with exception
Traceback (most recent call last):
  File "/home/airflow/.local/lib/python3.6/site-packages/airflow/models/taskinstance.py", line 1137, in _run_raw_task
    self._prepare_and_execute_task_with_callbacks(context, task)
  File "/home/airflow/.local/lib/python3.6/site-packages/airflow/models/taskinstance.py", line 1311, in _prepare_and_execute_task_with_callbacks
    result = self._execute_task(context, task_copy)
  File "/home/airflow/.local/lib/python3.6/site-packages/airflow/models/taskinstance.py", line 1341, in _execute_task
    result = task_copy.execute(context=context)
  File "/home/airflow/.local/lib/python3.6/site-packages/airflow/operators/python.py", line 150, in execute
    return_value = self.execute_callable()
  File "/home/airflow/.local/lib/python3.6/site-packages/airflow/operators/python.py", line 161, in execute_callable
    return self.python_callable(*self.op_args, **self.op_kwargs)
  File "/opt/airflow/dags/first_dag.py", line 183, in ambassador_refunds_type
    index=False)
  File "/home/airflow/.local/lib/python3.6/site-packages/pandas/core/generic.py", line 2615, in to_sql
    method=method,
  File "/home/airflow/.local/lib/python3.6/site-packages/pandas/io/sql.py", line 598, in to_sql
    method=method,
  File "/home/airflow/.local/lib/python3.6/site-packages/pandas/io/sql.py", line 1393, in to_sql
    table.create()
  File "/home/airflow/.local/lib/python3.6/site-packages/pandas/io/sql.py", line 725, in create
    self.pd_sql.drop_table(self.name, self.schema)
  File "/home/airflow/.local/lib/python3.6/site-packages/pandas/io/sql.py", line 1453, in drop_table
    self.meta.reflect(only=[table_name], schema=schema)
  File "/home/airflow/.local/lib/python3.6/site-packages/sqlalchemy/sql/schema.py", line 4612, in reflect
    "in %r%s: (%s)" % (bind.engine, s, ", ".join(missing))
sqlalchemy.exc.InvalidRequestError: Could not reflect: requested table(s) not available in Engine(mysql://root:***@host.docker.internal:3306/21north) schema '21north': (21N_ambassador_refunds_type)
[2021-06-14 15:28:11,598] {taskinstance.py:1531} INFO - Marking task as UP_FOR_RETRY. dag_id=summary_db, task_id=ambassador_refunds_type, execution_date=20210613T000000, start_date=20210614T152806, end_date=20210614T152811
[2021-06-14 15:28:12,032] {local_task_job.py:151} INFO - Task exited with return code 1
[2021-06-14 18:33:55,807] {taskinstance.py:876} INFO - Dependencies all met for <TaskInstance: summary_db.ambassador_refunds_type 2021-06-13T00:00:00+00:00 [queued]>
[2021-06-14 18:33:56,352] {taskinstance.py:876} INFO - Dependencies all met for <TaskInstance: summary_db.ambassador_refunds_type 2021-06-13T00:00:00+00:00 [queued]>
[2021-06-14 18:33:56,353] {taskinstance.py:1067} INFO - 
--------------------------------------------------------------------------------
[2021-06-14 18:33:56,353] {taskinstance.py:1068} INFO - Starting attempt 1 of 2
[2021-06-14 18:33:56,353] {taskinstance.py:1069} INFO - 
--------------------------------------------------------------------------------
[2021-06-14 18:33:56,671] {taskinstance.py:1087} INFO - Executing <Task(PythonOperator): ambassador_refunds_type> on 2021-06-13T00:00:00+00:00
[2021-06-14 18:33:56,744] {standard_task_runner.py:52} INFO - Started process 262 to run task
[2021-06-14 18:33:57,074] {standard_task_runner.py:76} INFO - Running: ['***', 'tasks', 'run', 'summary_db', 'ambassador_refunds_type', '2021-06-13T00:00:00+00:00', '--job-id', '114', '--pool', 'default_pool', '--raw', '--subdir', 'DAGS_FOLDER/first_dag.py', '--cfg-path', '/tmp/tmpu_9hr8qc', '--error-file', '/tmp/tmp408s9aqg']
[2021-06-14 18:33:57,075] {standard_task_runner.py:77} INFO - Job 114: Subtask ambassador_refunds_type
[2021-06-14 18:33:58,332] {logging_mixin.py:104} INFO - Running <TaskInstance: summary_db.ambassador_refunds_type 2021-06-13T00:00:00+00:00 [running]> on host 89c270a4555f
[2021-06-14 18:33:59,387] {taskinstance.py:1282} INFO - Exporting the following env vars:
AIRFLOW_CTX_DAG_OWNER=***
AIRFLOW_CTX_DAG_ID=summary_db
AIRFLOW_CTX_TASK_ID=ambassador_refunds_type
AIRFLOW_CTX_EXECUTION_DATE=2021-06-13T00:00:00+00:00
AIRFLOW_CTX_DAG_RUN_ID=scheduled__2021-06-13T00:00:00+00:00
[2021-06-14 18:33:59,464] {logging_mixin.py:104} INFO - ------------------------------------Inside Function-----------------------------
[2021-06-14 18:34:10,454] {logging_mixin.py:104} INFO - -------------------------------Data read into dataframe---------------------------
[2021-06-14 18:34:11,363] {logging_mixin.py:104} INFO - ----------------------------------Data written into summary DB----------------------
[2021-06-14 18:34:11,369] {python.py:151} INFO - Done. Returned value was: None
[2021-06-14 18:34:11,609] {taskinstance.py:1191} INFO - Marking task as SUCCESS. dag_id=summary_db, task_id=ambassador_refunds_type, execution_date=20210613T000000, start_date=20210614T183355, end_date=20210614T183411
[2021-06-14 18:34:12,612] {local_task_job.py:197} WARNING - State of this instance has been externally set to success. Terminating instance.
[2021-06-14 18:34:12,718] {taskinstance.py:1245} INFO - 0 downstream tasks scheduled from follow-on schedule check
[2021-06-14 18:34:12,642] {process_utils.py:100} INFO - Sending Signals.SIGTERM to GPID 262
[2021-06-14 18:34:13,107] {process_utils.py:66} INFO - Process psutil.Process(pid=262, status='terminated', exitcode=0, started='18:33:55') (262) terminated with exit code 0
