[2021-06-28 15:20:22,695] {taskinstance.py:876} INFO - Dependencies all met for <TaskInstance: summary_db.slot_tracker 2021-06-26T23:45:00+00:00 [queued]>
[2021-06-28 15:20:22,772] {taskinstance.py:876} INFO - Dependencies all met for <TaskInstance: summary_db.slot_tracker 2021-06-26T23:45:00+00:00 [queued]>
[2021-06-28 15:20:22,772] {taskinstance.py:1067} INFO - 
--------------------------------------------------------------------------------
[2021-06-28 15:20:22,773] {taskinstance.py:1068} INFO - Starting attempt 1 of 4
[2021-06-28 15:20:22,773] {taskinstance.py:1069} INFO - 
--------------------------------------------------------------------------------
[2021-06-28 15:20:22,841] {taskinstance.py:1087} INFO - Executing <Task(PythonOperator): slot_tracker> on 2021-06-26T23:45:00+00:00
[2021-06-28 15:20:22,924] {standard_task_runner.py:52} INFO - Started process 341 to run task
[2021-06-28 15:20:22,957] {standard_task_runner.py:76} INFO - Running: ['***', 'tasks', 'run', 'summary_db', 'slot_tracker', '2021-06-26T23:45:00+00:00', '--job-id', '292', '--pool', 'default_pool', '--raw', '--subdir', 'DAGS_FOLDER/analytics_summary.py', '--cfg-path', '/tmp/tmpomp312uh', '--error-file', '/tmp/tmphisz3wq1']
[2021-06-28 15:20:22,984] {standard_task_runner.py:77} INFO - Job 292: Subtask slot_tracker
[2021-06-28 15:20:23,447] {logging_mixin.py:104} INFO - Running <TaskInstance: summary_db.slot_tracker 2021-06-26T23:45:00+00:00 [running]> on host 32c9461fc328
[2021-06-28 15:20:23,693] {taskinstance.py:1282} INFO - Exporting the following env vars:
AIRFLOW_CTX_DAG_OWNER=***
AIRFLOW_CTX_DAG_ID=summary_db
AIRFLOW_CTX_TASK_ID=slot_tracker
AIRFLOW_CTX_EXECUTION_DATE=2021-06-26T23:45:00+00:00
AIRFLOW_CTX_DAG_RUN_ID=scheduled__2021-06-26T23:45:00+00:00
[2021-06-28 15:20:23,694] {logging_mixin.py:104} INFO - ------------------------------------Inside Function-----------------------------
[2021-06-28 15:20:27,527] {logging_mixin.py:104} INFO - -------------------------------Data read into dataframe---------------------------
[2021-06-28 15:20:27,598] {taskinstance.py:1481} ERROR - Task failed with exception
Traceback (most recent call last):
  File "/home/airflow/.local/lib/python3.6/site-packages/airflow/models/taskinstance.py", line 1137, in _run_raw_task
    self._prepare_and_execute_task_with_callbacks(context, task)
  File "/home/airflow/.local/lib/python3.6/site-packages/airflow/models/taskinstance.py", line 1311, in _prepare_and_execute_task_with_callbacks
    result = self._execute_task(context, task_copy)
  File "/home/airflow/.local/lib/python3.6/site-packages/airflow/models/taskinstance.py", line 1341, in _execute_task
    result = task_copy.execute(context=context)
  File "/home/airflow/.local/lib/python3.6/site-packages/airflow/operators/python.py", line 150, in execute
    return_value = self.execute_callable()
  File "/home/airflow/.local/lib/python3.6/site-packages/airflow/operators/python.py", line 161, in execute_callable
    return self.python_callable(*self.op_args, **self.op_kwargs)
  File "/opt/airflow/dags/analytics_summary.py", line 506, in slot_tracker
    df_slot_tracker['slot_hour'] = (pd.Timestamp('now').normalize() + df_slot_tracker['slot_hour']).dt.time
  File "/home/airflow/.local/lib/python3.6/site-packages/pandas/core/generic.py", line 5137, in __getattr__
    return object.__getattribute__(self, name)
  File "/home/airflow/.local/lib/python3.6/site-packages/pandas/core/accessor.py", line 187, in __get__
    accessor_obj = self._accessor(obj)
  File "/home/airflow/.local/lib/python3.6/site-packages/pandas/core/indexes/accessors.py", line 480, in __new__
    raise AttributeError("Can only use .dt accessor with datetimelike values")
AttributeError: Can only use .dt accessor with datetimelike values
[2021-06-28 15:20:27,670] {taskinstance.py:1531} INFO - Marking task as UP_FOR_RETRY. dag_id=summary_db, task_id=slot_tracker, execution_date=20210626T234500, start_date=20210628T152022, end_date=20210628T152027
[2021-06-28 15:20:27,846] {local_task_job.py:151} INFO - Task exited with return code 1
[2021-06-28 15:39:57,687] {taskinstance.py:876} INFO - Dependencies all met for <TaskInstance: summary_db.slot_tracker 2021-06-26T23:45:00+00:00 [queued]>
[2021-06-28 15:39:57,731] {taskinstance.py:876} INFO - Dependencies all met for <TaskInstance: summary_db.slot_tracker 2021-06-26T23:45:00+00:00 [queued]>
[2021-06-28 15:39:57,731] {taskinstance.py:1067} INFO - 
--------------------------------------------------------------------------------
[2021-06-28 15:39:57,731] {taskinstance.py:1068} INFO - Starting attempt 1 of 4
[2021-06-28 15:39:57,731] {taskinstance.py:1069} INFO - 
--------------------------------------------------------------------------------
[2021-06-28 15:39:57,746] {taskinstance.py:1087} INFO - Executing <Task(PythonOperator): slot_tracker> on 2021-06-26T23:45:00+00:00
[2021-06-28 15:39:57,755] {standard_task_runner.py:52} INFO - Started process 426 to run task
[2021-06-28 15:39:57,763] {standard_task_runner.py:76} INFO - Running: ['***', 'tasks', 'run', 'summary_db', 'slot_tracker', '2021-06-26T23:45:00+00:00', '--job-id', '321', '--pool', 'default_pool', '--raw', '--subdir', 'DAGS_FOLDER/analytics_summary.py', '--cfg-path', '/tmp/tmp14fwnwys', '--error-file', '/tmp/tmpsfycee5z']
[2021-06-28 15:39:57,764] {standard_task_runner.py:77} INFO - Job 321: Subtask slot_tracker
[2021-06-28 15:39:57,873] {logging_mixin.py:104} INFO - Running <TaskInstance: summary_db.slot_tracker 2021-06-26T23:45:00+00:00 [running]> on host 32c9461fc328
[2021-06-28 15:39:57,998] {taskinstance.py:1282} INFO - Exporting the following env vars:
AIRFLOW_CTX_DAG_OWNER=***
AIRFLOW_CTX_DAG_ID=summary_db
AIRFLOW_CTX_TASK_ID=slot_tracker
AIRFLOW_CTX_EXECUTION_DATE=2021-06-26T23:45:00+00:00
AIRFLOW_CTX_DAG_RUN_ID=scheduled__2021-06-26T23:45:00+00:00
[2021-06-28 15:39:58,000] {logging_mixin.py:104} INFO - ------------------------------------Inside Function-----------------------------
[2021-06-28 15:40:07,651] {logging_mixin.py:104} INFO - -------------------------------Data read into dataframe---------------------------
[2021-06-28 15:40:07,654] {taskinstance.py:1481} ERROR - Task failed with exception
Traceback (most recent call last):
  File "/home/airflow/.local/lib/python3.6/site-packages/airflow/models/taskinstance.py", line 1137, in _run_raw_task
    self._prepare_and_execute_task_with_callbacks(context, task)
  File "/home/airflow/.local/lib/python3.6/site-packages/airflow/models/taskinstance.py", line 1311, in _prepare_and_execute_task_with_callbacks
    result = self._execute_task(context, task_copy)
  File "/home/airflow/.local/lib/python3.6/site-packages/airflow/models/taskinstance.py", line 1341, in _execute_task
    result = task_copy.execute(context=context)
  File "/home/airflow/.local/lib/python3.6/site-packages/airflow/operators/python.py", line 150, in execute
    return_value = self.execute_callable()
  File "/home/airflow/.local/lib/python3.6/site-packages/airflow/operators/python.py", line 161, in execute_callable
    return self.python_callable(*self.op_args, **self.op_kwargs)
  File "/opt/airflow/dags/analytics_summary.py", line 506, in slot_tracker
    df_slot_tracker['slot_hour'] = (pd.Timestamp('now').normalize() + df_slot_tracker['slot_hour']).dt.time
  File "/home/airflow/.local/lib/python3.6/site-packages/pandas/core/generic.py", line 5137, in __getattr__
    return object.__getattribute__(self, name)
  File "/home/airflow/.local/lib/python3.6/site-packages/pandas/core/accessor.py", line 187, in __get__
    accessor_obj = self._accessor(obj)
  File "/home/airflow/.local/lib/python3.6/site-packages/pandas/core/indexes/accessors.py", line 480, in __new__
    raise AttributeError("Can only use .dt accessor with datetimelike values")
AttributeError: Can only use .dt accessor with datetimelike values
[2021-06-28 15:40:07,659] {taskinstance.py:1531} INFO - Marking task as UP_FOR_RETRY. dag_id=summary_db, task_id=slot_tracker, execution_date=20210626T234500, start_date=20210628T153957, end_date=20210628T154007
[2021-06-28 15:40:07,723] {local_task_job.py:151} INFO - Task exited with return code 1
