[2021-06-28 15:26:01,167] {taskinstance.py:876} INFO - Dependencies all met for <TaskInstance: summary_db.slot_tracker 2021-06-26T23:45:00+00:00 [queued]>
[2021-06-28 15:26:01,192] {taskinstance.py:876} INFO - Dependencies all met for <TaskInstance: summary_db.slot_tracker 2021-06-26T23:45:00+00:00 [queued]>
[2021-06-28 15:26:01,193] {taskinstance.py:1067} INFO - 
--------------------------------------------------------------------------------
[2021-06-28 15:26:01,193] {taskinstance.py:1068} INFO - Starting attempt 3 of 6
[2021-06-28 15:26:01,193] {taskinstance.py:1069} INFO - 
--------------------------------------------------------------------------------
[2021-06-28 15:26:01,205] {taskinstance.py:1087} INFO - Executing <Task(PythonOperator): slot_tracker> on 2021-06-26T23:45:00+00:00
[2021-06-28 15:26:01,213] {standard_task_runner.py:52} INFO - Started process 647 to run task
[2021-06-28 15:26:01,219] {standard_task_runner.py:76} INFO - Running: ['***', 'tasks', 'run', 'summary_db', 'slot_tracker', '2021-06-26T23:45:00+00:00', '--job-id', '294', '--pool', 'default_pool', '--raw', '--subdir', 'DAGS_FOLDER/analytics_summary.py', '--cfg-path', '/tmp/tmpio1u68ld', '--error-file', '/tmp/tmp3fhilt1p']
[2021-06-28 15:26:01,219] {standard_task_runner.py:77} INFO - Job 294: Subtask slot_tracker
[2021-06-28 15:26:01,280] {logging_mixin.py:104} INFO - Running <TaskInstance: summary_db.slot_tracker 2021-06-26T23:45:00+00:00 [running]> on host 32c9461fc328
[2021-06-28 15:26:01,342] {taskinstance.py:1282} INFO - Exporting the following env vars:
AIRFLOW_CTX_DAG_OWNER=***
AIRFLOW_CTX_DAG_ID=summary_db
AIRFLOW_CTX_TASK_ID=slot_tracker
AIRFLOW_CTX_EXECUTION_DATE=2021-06-26T23:45:00+00:00
AIRFLOW_CTX_DAG_RUN_ID=scheduled__2021-06-26T23:45:00+00:00
[2021-06-28 15:26:01,343] {logging_mixin.py:104} INFO - ------------------------------------Inside Function-----------------------------
[2021-06-28 15:26:21,501] {logging_mixin.py:104} INFO - -------------------------------Data read into dataframe---------------------------
[2021-06-28 15:26:21,512] {taskinstance.py:1481} ERROR - Task failed with exception
Traceback (most recent call last):
  File "/home/airflow/.local/lib/python3.6/site-packages/airflow/models/taskinstance.py", line 1137, in _run_raw_task
    self._prepare_and_execute_task_with_callbacks(context, task)
  File "/home/airflow/.local/lib/python3.6/site-packages/airflow/models/taskinstance.py", line 1311, in _prepare_and_execute_task_with_callbacks
    result = self._execute_task(context, task_copy)
  File "/home/airflow/.local/lib/python3.6/site-packages/airflow/models/taskinstance.py", line 1341, in _execute_task
    result = task_copy.execute(context=context)
  File "/home/airflow/.local/lib/python3.6/site-packages/airflow/operators/python.py", line 150, in execute
    return_value = self.execute_callable()
  File "/home/airflow/.local/lib/python3.6/site-packages/airflow/operators/python.py", line 161, in execute_callable
    return self.python_callable(*self.op_args, **self.op_kwargs)
  File "/opt/airflow/dags/analytics_summary.py", line 506, in slot_tracker
    df_slot_tracker['slot_hour'] = (pd.Timestamp('now').normalize() + df_slot_tracker['slot_hour']).dt.time
  File "/home/airflow/.local/lib/python3.6/site-packages/pandas/core/generic.py", line 5137, in __getattr__
    return object.__getattribute__(self, name)
  File "/home/airflow/.local/lib/python3.6/site-packages/pandas/core/accessor.py", line 187, in __get__
    accessor_obj = self._accessor(obj)
  File "/home/airflow/.local/lib/python3.6/site-packages/pandas/core/indexes/accessors.py", line 480, in __new__
    raise AttributeError("Can only use .dt accessor with datetimelike values")
AttributeError: Can only use .dt accessor with datetimelike values
[2021-06-28 15:26:21,518] {taskinstance.py:1531} INFO - Marking task as UP_FOR_RETRY. dag_id=summary_db, task_id=slot_tracker, execution_date=20210626T234500, start_date=20210628T152601, end_date=20210628T152621
[2021-06-28 15:26:21,569] {local_task_job.py:151} INFO - Task exited with return code 1
