[2021-06-15 17:51:06,015] {taskinstance.py:876} INFO - Dependencies all met for <TaskInstance: summary_db.queue_distance_eta 2021-06-14T00:00:00+00:00 [queued]>
[2021-06-15 17:51:06,397] {taskinstance.py:876} INFO - Dependencies all met for <TaskInstance: summary_db.queue_distance_eta 2021-06-14T00:00:00+00:00 [queued]>
[2021-06-15 17:51:06,397] {taskinstance.py:1067} INFO - 
--------------------------------------------------------------------------------
[2021-06-15 17:51:06,399] {taskinstance.py:1068} INFO - Starting attempt 1 of 2
[2021-06-15 17:51:06,401] {taskinstance.py:1069} INFO - 
--------------------------------------------------------------------------------
[2021-06-15 17:51:06,584] {taskinstance.py:1087} INFO - Executing <Task(PythonOperator): queue_distance_eta> on 2021-06-14T00:00:00+00:00
[2021-06-15 17:51:06,746] {standard_task_runner.py:52} INFO - Started process 945 to run task
[2021-06-15 17:51:06,922] {standard_task_runner.py:76} INFO - Running: ['***', 'tasks', 'run', 'summary_db', 'queue_distance_eta', '2021-06-14T00:00:00+00:00', '--job-id', '136', '--pool', 'default_pool', '--raw', '--subdir', 'DAGS_FOLDER/first_dag.py', '--cfg-path', '/tmp/tmp6if52ml8', '--error-file', '/tmp/tmp_pxwl1dq']
[2021-06-15 17:51:06,922] {standard_task_runner.py:77} INFO - Job 136: Subtask queue_distance_eta
[2021-06-15 17:51:07,582] {logging_mixin.py:104} INFO - Running <TaskInstance: summary_db.queue_distance_eta 2021-06-14T00:00:00+00:00 [running]> on host bb8bb196dd92
[2021-06-15 17:51:08,978] {taskinstance.py:1282} INFO - Exporting the following env vars:
AIRFLOW_CTX_DAG_OWNER=***
AIRFLOW_CTX_DAG_ID=summary_db
AIRFLOW_CTX_TASK_ID=queue_distance_eta
AIRFLOW_CTX_EXECUTION_DATE=2021-06-14T00:00:00+00:00
AIRFLOW_CTX_DAG_RUN_ID=scheduled__2021-06-14T00:00:00+00:00
[2021-06-15 17:51:08,980] {logging_mixin.py:104} INFO - ------------------------------------Inside Function-----------------------------
[2021-06-15 17:52:49,971] {logging_mixin.py:104} INFO - -------------------------------Data read into dataframe---------------------------
[2021-06-15 17:52:51,542] {logging_mixin.py:104} WARNING - /home/***/.local/lib/python3.6/site-packages/pandas/io/sql.py:1423 UserWarning: The provided table name '21N_queue_distance_eta' is not found exactly as such in the database after writing the table, possibly due to case sensitivity issues. Consider using lower case table names.
[2021-06-15 17:52:51,543] {logging_mixin.py:104} INFO - ----------------------------------Data written into summary DB----------------------
[2021-06-15 17:52:51,544] {python.py:151} INFO - Done. Returned value was: None
[2021-06-15 17:52:51,631] {taskinstance.py:1191} INFO - Marking task as SUCCESS. dag_id=summary_db, task_id=queue_distance_eta, execution_date=20210614T000000, start_date=20210615T175106, end_date=20210615T175251
[2021-06-15 17:52:52,126] {taskinstance.py:1245} INFO - 0 downstream tasks scheduled from follow-on schedule check
[2021-06-15 17:52:52,189] {local_task_job.py:151} INFO - Task exited with return code 0
