[2021-06-16 13:26:53,048] {taskinstance.py:876} INFO - Dependencies all met for <TaskInstance: summary_db.ambassador_locationbk 2021-06-15T02:30:00+00:00 [queued]>
[2021-06-16 13:26:53,137] {taskinstance.py:876} INFO - Dependencies all met for <TaskInstance: summary_db.ambassador_locationbk 2021-06-15T02:30:00+00:00 [queued]>
[2021-06-16 13:26:53,137] {taskinstance.py:1067} INFO - 
--------------------------------------------------------------------------------
[2021-06-16 13:26:53,138] {taskinstance.py:1068} INFO - Starting attempt 3 of 5
[2021-06-16 13:26:53,138] {taskinstance.py:1069} INFO - 
--------------------------------------------------------------------------------
[2021-06-16 13:26:53,206] {taskinstance.py:1087} INFO - Executing <Task(PythonOperator): ambassador_locationbk> on 2021-06-15T02:30:00+00:00
[2021-06-16 13:26:53,242] {standard_task_runner.py:52} INFO - Started process 2487 to run task
[2021-06-16 13:26:53,263] {standard_task_runner.py:76} INFO - Running: ['***', 'tasks', 'run', 'summary_db', 'ambassador_locationbk', '2021-06-15T02:30:00+00:00', '--job-id', '258', '--pool', 'default_pool', '--raw', '--subdir', 'DAGS_FOLDER/first_dag.py', '--cfg-path', '/tmp/tmpmenpmh79', '--error-file', '/tmp/tmpqb20rxz3']
[2021-06-16 13:26:53,263] {standard_task_runner.py:77} INFO - Job 258: Subtask ambassador_locationbk
[2021-06-16 13:26:53,532] {logging_mixin.py:104} INFO - Running <TaskInstance: summary_db.ambassador_locationbk 2021-06-15T02:30:00+00:00 [running]> on host ac3e7c1eb084
[2021-06-16 13:26:53,707] {taskinstance.py:1282} INFO - Exporting the following env vars:
AIRFLOW_CTX_DAG_OWNER=***
AIRFLOW_CTX_DAG_ID=summary_db
AIRFLOW_CTX_TASK_ID=ambassador_locationbk
AIRFLOW_CTX_EXECUTION_DATE=2021-06-15T02:30:00+00:00
AIRFLOW_CTX_DAG_RUN_ID=scheduled__2021-06-15T02:30:00+00:00
[2021-06-16 13:26:53,708] {logging_mixin.py:104} INFO - ------------------------------------Inside Function-----------------------------
[2021-06-16 13:27:10,163] {logging_mixin.py:104} INFO - -------------------------------Data read into dataframe---------------------------
[2021-06-16 13:27:15,866] {taskinstance.py:1481} ERROR - Task failed with exception
Traceback (most recent call last):
  File "/home/airflow/.local/lib/python3.6/site-packages/sqlalchemy/engine/base.py", line 1257, in _execute_context
    cursor, statement, parameters, context
  File "/home/airflow/.local/lib/python3.6/site-packages/sqlalchemy/dialects/mysql/mysqldb.py", line 148, in do_executemany
    rowcount = cursor.executemany(statement, parameters)
  File "/home/airflow/.local/lib/python3.6/site-packages/MySQLdb/cursors.py", line 236, in executemany
    self._get_db().encoding,
  File "/home/airflow/.local/lib/python3.6/site-packages/MySQLdb/cursors.py", line 261, in _do_execute_many
    rows += self.execute(sql + postfix)
  File "/home/airflow/.local/lib/python3.6/site-packages/MySQLdb/cursors.py", line 206, in execute
    res = self._query(query)
  File "/home/airflow/.local/lib/python3.6/site-packages/MySQLdb/cursors.py", line 319, in _query
    db.query(q)
  File "/home/airflow/.local/lib/python3.6/site-packages/MySQLdb/connections.py", line 259, in query
    _mysql.connection.query(self, query)
MySQLdb._exceptions.IntegrityError: (1062, "Duplicate entry '202560585' for key 'PRIMARY'")

The above exception was the direct cause of the following exception:

Traceback (most recent call last):
  File "/home/airflow/.local/lib/python3.6/site-packages/airflow/models/taskinstance.py", line 1137, in _run_raw_task
    self._prepare_and_execute_task_with_callbacks(context, task)
  File "/home/airflow/.local/lib/python3.6/site-packages/airflow/models/taskinstance.py", line 1311, in _prepare_and_execute_task_with_callbacks
    result = self._execute_task(context, task_copy)
  File "/home/airflow/.local/lib/python3.6/site-packages/airflow/models/taskinstance.py", line 1341, in _execute_task
    result = task_copy.execute(context=context)
  File "/home/airflow/.local/lib/python3.6/site-packages/airflow/operators/python.py", line 150, in execute
    return_value = self.execute_callable()
  File "/home/airflow/.local/lib/python3.6/site-packages/airflow/operators/python.py", line 161, in execute_callable
    return self.python_callable(*self.op_args, **self.op_kwargs)
  File "/opt/airflow/dags/first_dag.py", line 131, in ambassador_locationbk
    index=False)
  File "/home/airflow/.local/lib/python3.6/site-packages/pandas/core/generic.py", line 2615, in to_sql
    method=method,
  File "/home/airflow/.local/lib/python3.6/site-packages/pandas/io/sql.py", line 598, in to_sql
    method=method,
  File "/home/airflow/.local/lib/python3.6/site-packages/pandas/io/sql.py", line 1406, in to_sql
    raise err
  File "/home/airflow/.local/lib/python3.6/site-packages/pandas/io/sql.py", line 1398, in to_sql
    table.insert(chunksize, method=method)
  File "/home/airflow/.local/lib/python3.6/site-packages/pandas/io/sql.py", line 830, in insert
    exec_insert(conn, keys, chunk_iter)
  File "/home/airflow/.local/lib/python3.6/site-packages/pandas/io/sql.py", line 747, in _execute_insert
    conn.execute(self.table.insert(), data)
  File "/home/airflow/.local/lib/python3.6/site-packages/sqlalchemy/engine/base.py", line 1011, in execute
    return meth(self, multiparams, params)
  File "/home/airflow/.local/lib/python3.6/site-packages/sqlalchemy/sql/elements.py", line 298, in _execute_on_connection
    return connection._execute_clauseelement(self, multiparams, params)
  File "/home/airflow/.local/lib/python3.6/site-packages/sqlalchemy/engine/base.py", line 1130, in _execute_clauseelement
    distilled_params,
  File "/home/airflow/.local/lib/python3.6/site-packages/sqlalchemy/engine/base.py", line 1317, in _execute_context
    e, statement, parameters, cursor, context
  File "/home/airflow/.local/lib/python3.6/site-packages/sqlalchemy/engine/base.py", line 1511, in _handle_dbapi_exception
    sqlalchemy_exception, with_traceback=exc_info[2], from_=e
  File "/home/airflow/.local/lib/python3.6/site-packages/sqlalchemy/util/compat.py", line 182, in raise_
    raise exception
  File "/home/airflow/.local/lib/python3.6/site-packages/sqlalchemy/engine/base.py", line 1257, in _execute_context
    cursor, statement, parameters, context
  File "/home/airflow/.local/lib/python3.6/site-packages/sqlalchemy/dialects/mysql/mysqldb.py", line 148, in do_executemany
    rowcount = cursor.executemany(statement, parameters)
  File "/home/airflow/.local/lib/python3.6/site-packages/MySQLdb/cursors.py", line 236, in executemany
    self._get_db().encoding,
  File "/home/airflow/.local/lib/python3.6/site-packages/MySQLdb/cursors.py", line 261, in _do_execute_many
    rows += self.execute(sql + postfix)
  File "/home/airflow/.local/lib/python3.6/site-packages/MySQLdb/cursors.py", line 206, in execute
    res = self._query(query)
  File "/home/airflow/.local/lib/python3.6/site-packages/MySQLdb/cursors.py", line 319, in _query
    db.query(q)
  File "/home/airflow/.local/lib/python3.6/site-packages/MySQLdb/connections.py", line 259, in query
    _mysql.connection.query(self, query)
sqlalchemy.exc.IntegrityError: (MySQLdb._exceptions.IntegrityError) (1062, "Duplicate entry '202560585' for key 'PRIMARY'")
[SQL: INSERT INTO analytics.`21N_ambassador_locationbk` (id, ambassador_id, presentlat, presentlong, presenttime, altitude, speed, course, devicetoken, version, iscurrent, queueid, state) VALUES (%s, %s, %s, %s, %s, %s, %s, %s, %s, %s, %s, %s, %s)]
[parameters: ((202560585, 812610, 22.5955415, 88.36513845, datetime.datetime(2021, 6, 15, 18, 56, 56), -59.27, 0.0, '0', '8c9639a647ad17b3', '2.3.0', 0, 1635392, 612), (202560586, 812605, 26.8799463612959, 75.8030728809536, datetime.datetime(2021, 6, 15, 18, 56, 56), 379.0, 1.079999936, '0', '2fc79346b210bfa1', '2.3.0', 0, 1637609, 902), (202560587, 859177, 22.97157444, 72.58830664, datetime.datetime(2021, 6, 15, 18, 56, 56), -8.98, 23.580000687, '358.70001220703125', '42d1fc9141a514a7', '2.3.0', 0, 1638468, 4300), (202560588, 35263, 28.5746911, 77.1785046, datetime.datetime(2021, 6, 15, 18, 56, 57), 186.79, 0.013025665, '158.59364318847656', '650559f145a1ae88', '2.3.0', 0, 1636889, 722), (202560589, 604929, 28.8118815422058, 77.0108342170715, datetime.datetime(2021, 6, 15, 18, 56, 57), 167.43, 11.771999931, '22.8515625', '6038501dde1e198f', '2.3.0', 0, 1636167, 602), (202560590, 837633, 28.5174523, 77.2820526, datetime.datetime(2021, 6, 15, 18, 56, 59), 169.92, 0.0, '0', '0acd459c49abede2', '2.3.0', 0, 1636660, 602), (202560591, 738711, 23.04589685, 72.53048956, datetime.datetime(2021, 6, 15, 18, 56, 59), 6.88, 7.271999931, '221.8000030517578', '46cc480b4c81733d', '2.3.0', 0, 1636868, 612), (202560592, 851763, 22.9455452, 72.5922816, datetime.datetime(2021, 6, 15, 18, 56, 59), -23.38, 27.396000481, '349.70001220703125', '9f520c95437abc8f', '2.3.0', 0, 1638359, 410)  ... displaying 10 of 51609 total bound parameter sets ...  (202612193, 850223, 28.7195297749713, 77.1257469244301, datetime.datetime(2021, 6, 16, 10, 4, 19), 169.0, 3.743999863, '215.3000030517578', '95f9c549002927ed', '2.3.0', 0, 1638162, 110), (202612194, 614005, 18.5044283333333, 73.8273666666667, datetime.datetime(2021, 6, 16, 10, 4, 19), 563.3, 31.295317841, '193.77000427246094', 'd4d4e7165fb9df8e', '2.3.0', 0, 1638317, 250))]
(Background on this error at: http://sqlalche.me/e/13/gkpj)
[2021-06-16 13:27:16,375] {taskinstance.py:1531} INFO - Marking task as UP_FOR_RETRY. dag_id=summary_db, task_id=ambassador_locationbk, execution_date=20210615T023000, start_date=20210616T132653, end_date=20210616T132716
[2021-06-16 13:27:16,440] {local_task_job.py:151} INFO - Task exited with return code 1
