[2021-06-14 05:32:54,982] {taskinstance.py:876} INFO - Dependencies all met for <TaskInstance: summary_db.ambassador_channel_partner_comission 2021-06-13T00:00:00+00:00 [queued]>
[2021-06-14 05:32:55,171] {taskinstance.py:876} INFO - Dependencies all met for <TaskInstance: summary_db.ambassador_channel_partner_comission 2021-06-13T00:00:00+00:00 [queued]>
[2021-06-14 05:32:55,171] {taskinstance.py:1067} INFO - 
--------------------------------------------------------------------------------
[2021-06-14 05:32:55,172] {taskinstance.py:1068} INFO - Starting attempt 1 of 2
[2021-06-14 05:32:55,172] {taskinstance.py:1069} INFO - 
--------------------------------------------------------------------------------
[2021-06-14 05:32:55,266] {taskinstance.py:1087} INFO - Executing <Task(PythonOperator): ambassador_channel_partner_comission> on 2021-06-13T00:00:00+00:00
[2021-06-14 05:32:55,295] {standard_task_runner.py:52} INFO - Started process 211 to run task
[2021-06-14 05:32:55,312] {standard_task_runner.py:76} INFO - Running: ['***', 'tasks', 'run', 'summary_db', 'ambassador_channel_partner_comission', '2021-06-13T00:00:00+00:00', '--job-id', '31', '--pool', 'default_pool', '--raw', '--subdir', 'DAGS_FOLDER/first_dag.py', '--cfg-path', '/tmp/tmp9sqb7wru', '--error-file', '/tmp/tmp1zhqve6r']
[2021-06-14 05:32:55,313] {standard_task_runner.py:77} INFO - Job 31: Subtask ambassador_channel_partner_comission
[2021-06-14 05:32:55,582] {logging_mixin.py:104} INFO - Running <TaskInstance: summary_db.ambassador_channel_partner_comission 2021-06-13T00:00:00+00:00 [running]> on host cd286abfa59f
[2021-06-14 05:32:55,852] {taskinstance.py:1282} INFO - Exporting the following env vars:
AIRFLOW_CTX_DAG_OWNER=***
AIRFLOW_CTX_DAG_ID=summary_db
AIRFLOW_CTX_TASK_ID=ambassador_channel_partner_comission
AIRFLOW_CTX_EXECUTION_DATE=2021-06-13T00:00:00+00:00
AIRFLOW_CTX_DAG_RUN_ID=scheduled__2021-06-13T00:00:00+00:00
[2021-06-14 05:32:55,859] {logging_mixin.py:104} INFO - ------------------------------------Inside Function-----------------------------
[2021-06-14 05:32:58,996] {logging_mixin.py:104} INFO - -------------------------------Data read into dataframe---------------------------
[2021-06-14 05:33:00,056] {logging_mixin.py:104} WARNING - /home/***/.local/lib/python3.6/site-packages/pandas/io/sql.py:1423 UserWarning: The provided table name '21N_ambassador_channel_partner_comission' is not found exactly as such in the database after writing the table, possibly due to case sensitivity issues. Consider using lower case table names.
[2021-06-14 05:33:00,057] {logging_mixin.py:104} INFO - ----------------------------------Data written into summary DB----------------------
[2021-06-14 05:33:00,057] {python.py:151} INFO - Done. Returned value was: None
[2021-06-14 05:33:00,106] {taskinstance.py:1191} INFO - Marking task as SUCCESS. dag_id=summary_db, task_id=ambassador_channel_partner_comission, execution_date=20210613T000000, start_date=20210614T053254, end_date=20210614T053300
[2021-06-14 05:33:00,210] {taskinstance.py:1245} INFO - 0 downstream tasks scheduled from follow-on schedule check
[2021-06-14 05:33:00,253] {local_task_job.py:151} INFO - Task exited with return code 0
[2021-06-14 12:48:59,735] {taskinstance.py:876} INFO - Dependencies all met for <TaskInstance: summary_db.ambassador_channel_partner_comission 2021-06-13T00:00:00+00:00 [queued]>
[2021-06-14 12:49:00,008] {taskinstance.py:876} INFO - Dependencies all met for <TaskInstance: summary_db.ambassador_channel_partner_comission 2021-06-13T00:00:00+00:00 [queued]>
[2021-06-14 12:49:00,008] {taskinstance.py:1067} INFO - 
--------------------------------------------------------------------------------
[2021-06-14 12:49:00,008] {taskinstance.py:1068} INFO - Starting attempt 1 of 2
[2021-06-14 12:49:00,008] {taskinstance.py:1069} INFO - 
--------------------------------------------------------------------------------
[2021-06-14 12:49:00,106] {taskinstance.py:1087} INFO - Executing <Task(PythonOperator): ambassador_channel_partner_comission> on 2021-06-13T00:00:00+00:00
[2021-06-14 12:49:00,174] {standard_task_runner.py:52} INFO - Started process 370 to run task
[2021-06-14 12:49:00,223] {standard_task_runner.py:76} INFO - Running: ['***', 'tasks', 'run', 'summary_db', 'ambassador_channel_partner_comission', '2021-06-13T00:00:00+00:00', '--job-id', '39', '--pool', 'default_pool', '--raw', '--subdir', 'DAGS_FOLDER/first_dag.py', '--cfg-path', '/tmp/tmpcfg0sggu', '--error-file', '/tmp/tmp04v8q1jc']
[2021-06-14 12:49:00,223] {standard_task_runner.py:77} INFO - Job 39: Subtask ambassador_channel_partner_comission
[2021-06-14 12:49:00,740] {logging_mixin.py:104} INFO - Running <TaskInstance: summary_db.ambassador_channel_partner_comission 2021-06-13T00:00:00+00:00 [running]> on host 7874826b9cd7
[2021-06-14 12:49:01,374] {taskinstance.py:1282} INFO - Exporting the following env vars:
AIRFLOW_CTX_DAG_OWNER=***
AIRFLOW_CTX_DAG_ID=summary_db
AIRFLOW_CTX_TASK_ID=ambassador_channel_partner_comission
AIRFLOW_CTX_EXECUTION_DATE=2021-06-13T00:00:00+00:00
AIRFLOW_CTX_DAG_RUN_ID=scheduled__2021-06-13T00:00:00+00:00
[2021-06-14 12:49:01,386] {logging_mixin.py:104} INFO - ------------------------------------Inside Function-----------------------------
[2021-06-14 12:49:06,900] {logging_mixin.py:104} INFO - -------------------------------Data read into dataframe---------------------------
[2021-06-14 12:49:07,902] {taskinstance.py:1481} ERROR - Task failed with exception
Traceback (most recent call last):
  File "/home/airflow/.local/lib/python3.6/site-packages/sqlalchemy/engine/base.py", line 1257, in _execute_context
    cursor, statement, parameters, context
  File "/home/airflow/.local/lib/python3.6/site-packages/sqlalchemy/dialects/mysql/mysqldb.py", line 148, in do_executemany
    rowcount = cursor.executemany(statement, parameters)
  File "/home/airflow/.local/lib/python3.6/site-packages/MySQLdb/cursors.py", line 236, in executemany
    self._get_db().encoding,
  File "/home/airflow/.local/lib/python3.6/site-packages/MySQLdb/cursors.py", line 261, in _do_execute_many
    rows += self.execute(sql + postfix)
  File "/home/airflow/.local/lib/python3.6/site-packages/MySQLdb/cursors.py", line 206, in execute
    res = self._query(query)
  File "/home/airflow/.local/lib/python3.6/site-packages/MySQLdb/cursors.py", line 319, in _query
    db.query(q)
  File "/home/airflow/.local/lib/python3.6/site-packages/MySQLdb/connections.py", line 259, in query
    _mysql.connection.query(self, query)
MySQLdb._exceptions.IntegrityError: (1062, "Duplicate entry '1699989' for key '21n_ambassador_channel_partner_comission.PRIMARY'")

The above exception was the direct cause of the following exception:

Traceback (most recent call last):
  File "/home/airflow/.local/lib/python3.6/site-packages/airflow/models/taskinstance.py", line 1137, in _run_raw_task
    self._prepare_and_execute_task_with_callbacks(context, task)
  File "/home/airflow/.local/lib/python3.6/site-packages/airflow/models/taskinstance.py", line 1311, in _prepare_and_execute_task_with_callbacks
    result = self._execute_task(context, task_copy)
  File "/home/airflow/.local/lib/python3.6/site-packages/airflow/models/taskinstance.py", line 1341, in _execute_task
    result = task_copy.execute(context=context)
  File "/home/airflow/.local/lib/python3.6/site-packages/airflow/operators/python.py", line 150, in execute
    return_value = self.execute_callable()
  File "/home/airflow/.local/lib/python3.6/site-packages/airflow/operators/python.py", line 161, in execute_callable
    return self.python_callable(*self.op_args, **self.op_kwargs)
  File "/opt/airflow/dags/first_dag.py", line 30, in ambassador_channel_partner_comission
    index=False)
  File "/home/airflow/.local/lib/python3.6/site-packages/pandas/core/generic.py", line 2615, in to_sql
    method=method,
  File "/home/airflow/.local/lib/python3.6/site-packages/pandas/io/sql.py", line 598, in to_sql
    method=method,
  File "/home/airflow/.local/lib/python3.6/site-packages/pandas/io/sql.py", line 1406, in to_sql
    raise err
  File "/home/airflow/.local/lib/python3.6/site-packages/pandas/io/sql.py", line 1398, in to_sql
    table.insert(chunksize, method=method)
  File "/home/airflow/.local/lib/python3.6/site-packages/pandas/io/sql.py", line 830, in insert
    exec_insert(conn, keys, chunk_iter)
  File "/home/airflow/.local/lib/python3.6/site-packages/pandas/io/sql.py", line 747, in _execute_insert
    conn.execute(self.table.insert(), data)
  File "/home/airflow/.local/lib/python3.6/site-packages/sqlalchemy/engine/base.py", line 1011, in execute
    return meth(self, multiparams, params)
  File "/home/airflow/.local/lib/python3.6/site-packages/sqlalchemy/sql/elements.py", line 298, in _execute_on_connection
    return connection._execute_clauseelement(self, multiparams, params)
  File "/home/airflow/.local/lib/python3.6/site-packages/sqlalchemy/engine/base.py", line 1130, in _execute_clauseelement
    distilled_params,
  File "/home/airflow/.local/lib/python3.6/site-packages/sqlalchemy/engine/base.py", line 1317, in _execute_context
    e, statement, parameters, cursor, context
  File "/home/airflow/.local/lib/python3.6/site-packages/sqlalchemy/engine/base.py", line 1511, in _handle_dbapi_exception
    sqlalchemy_exception, with_traceback=exc_info[2], from_=e
  File "/home/airflow/.local/lib/python3.6/site-packages/sqlalchemy/util/compat.py", line 182, in raise_
    raise exception
  File "/home/airflow/.local/lib/python3.6/site-packages/sqlalchemy/engine/base.py", line 1257, in _execute_context
    cursor, statement, parameters, context
  File "/home/airflow/.local/lib/python3.6/site-packages/sqlalchemy/dialects/mysql/mysqldb.py", line 148, in do_executemany
    rowcount = cursor.executemany(statement, parameters)
  File "/home/airflow/.local/lib/python3.6/site-packages/MySQLdb/cursors.py", line 236, in executemany
    self._get_db().encoding,
  File "/home/airflow/.local/lib/python3.6/site-packages/MySQLdb/cursors.py", line 261, in _do_execute_many
    rows += self.execute(sql + postfix)
  File "/home/airflow/.local/lib/python3.6/site-packages/MySQLdb/cursors.py", line 206, in execute
    res = self._query(query)
  File "/home/airflow/.local/lib/python3.6/site-packages/MySQLdb/cursors.py", line 319, in _query
    db.query(q)
  File "/home/airflow/.local/lib/python3.6/site-packages/MySQLdb/connections.py", line 259, in query
    _mysql.connection.query(self, query)
sqlalchemy.exc.IntegrityError: (MySQLdb._exceptions.IntegrityError) (1062, "Duplicate entry '1699989' for key '21n_ambassador_channel_partner_comission.PRIMARY'")
[SQL: INSERT INTO `21north`.`21N_ambassador_channel_partner_comission` (id, creationdate, channel_partner_id, ambid, queueid, state, amount, tmpamount, reason, taskcount, channel_comission, settled, settled_by, settlement_datetime) VALUES (%s, %s, %s, %s, %s, %s, %s, %s, %s, %s, %s, %s, %s, %s)]
[parameters: ((1699989, datetime.datetime(2021, 6, 13, 18, 20, 9), 64, 705743, 1633384, 802, 0.0, 0, None, 1.0, 0.0, 0, None, None), (1699990, datetime.datetime(2021, 6, 13, 18, 20, 43), 127, 649512, 1631961, 111, 0.0, 0, None, 0.0, 0.0, 0, None, None), (1699991, datetime.datetime(2021, 6, 13, 18, 23, 1), 140, 118985, 1632342, 111, 0.0, 0, None, 0.0, 0.0, 0, None, None), (1699992, datetime.datetime(2021, 6, 13, 18, 24, 38), 74, 175244, 1634178, 111, 0.0, 0, None, 0.0, 0.0, 0, None, None), (1699993, datetime.datetime(2021, 6, 13, 18, 24, 38), 64, 705742, 1634814, 802, 0.0, 0, None, 2.0, 0.0, 0, None, None), (1699994, datetime.datetime(2021, 6, 13, 18, 24, 41), 47, 590682, 1633765, 802, 0.0, 0, None, 1.0, 0.0, 0, None, None), (1699995, datetime.datetime(2021, 6, 13, 18, 24, 59), 170, 619991, 1633854, 802, 0.0, 0, None, 2.0, 0.0, 0, None, None), (1699996, datetime.datetime(2021, 6, 13, 18, 25, 12), 160, 808972, 1633524, 802, 0.0, 0, None, 1.0, 0.0, 0, None, None)  ... displaying 10 of 1706 total bound parameter sets ...  (1701703, datetime.datetime(2021, 6, 14, 14, 32, 15), 188, 858233, 1634924, 802, 0.0, 0, None, 1.0, 0.0, 0, None, None), (1701704, datetime.datetime(2021, 6, 14, 14, 35, 5), 132, 848474, 1630194, 802, 0.0, 0, None, 1.0, 0.0, 0, None, None))]
(Background on this error at: http://sqlalche.me/e/13/gkpj)
[2021-06-14 12:49:08,051] {taskinstance.py:1531} INFO - Marking task as UP_FOR_RETRY. dag_id=summary_db, task_id=ambassador_channel_partner_comission, execution_date=20210613T000000, start_date=20210614T124859, end_date=20210614T124908
[2021-06-14 12:49:08,273] {local_task_job.py:151} INFO - Task exited with return code 1
[2021-06-14 15:28:05,053] {taskinstance.py:876} INFO - Dependencies all met for <TaskInstance: summary_db.ambassador_channel_partner_comission 2021-06-13T00:00:00+00:00 [queued]>
[2021-06-14 15:28:05,348] {taskinstance.py:876} INFO - Dependencies all met for <TaskInstance: summary_db.ambassador_channel_partner_comission 2021-06-13T00:00:00+00:00 [queued]>
[2021-06-14 15:28:05,348] {taskinstance.py:1067} INFO - 
--------------------------------------------------------------------------------
[2021-06-14 15:28:05,348] {taskinstance.py:1068} INFO - Starting attempt 1 of 2
[2021-06-14 15:28:05,349] {taskinstance.py:1069} INFO - 
--------------------------------------------------------------------------------
[2021-06-14 15:28:05,561] {taskinstance.py:1087} INFO - Executing <Task(PythonOperator): ambassador_channel_partner_comission> on 2021-06-13T00:00:00+00:00
[2021-06-14 15:28:05,638] {standard_task_runner.py:52} INFO - Started process 791 to run task
[2021-06-14 15:28:05,714] {standard_task_runner.py:76} INFO - Running: ['***', 'tasks', 'run', 'summary_db', 'ambassador_channel_partner_comission', '2021-06-13T00:00:00+00:00', '--job-id', '70', '--pool', 'default_pool', '--raw', '--subdir', 'DAGS_FOLDER/first_dag.py', '--cfg-path', '/tmp/tmpi9jr6fj2', '--error-file', '/tmp/tmp0tyh7d5t']
[2021-06-14 15:28:05,715] {standard_task_runner.py:77} INFO - Job 70: Subtask ambassador_channel_partner_comission
[2021-06-14 15:28:06,249] {logging_mixin.py:104} INFO - Running <TaskInstance: summary_db.ambassador_channel_partner_comission 2021-06-13T00:00:00+00:00 [running]> on host 7874826b9cd7
[2021-06-14 15:28:06,940] {taskinstance.py:1282} INFO - Exporting the following env vars:
AIRFLOW_CTX_DAG_OWNER=***
AIRFLOW_CTX_DAG_ID=summary_db
AIRFLOW_CTX_TASK_ID=ambassador_channel_partner_comission
AIRFLOW_CTX_EXECUTION_DATE=2021-06-13T00:00:00+00:00
AIRFLOW_CTX_DAG_RUN_ID=scheduled__2021-06-13T00:00:00+00:00
[2021-06-14 15:28:06,943] {logging_mixin.py:104} INFO - ------------------------------------Inside Function-----------------------------
[2021-06-14 15:28:10,591] {logging_mixin.py:104} INFO - -------------------------------Data read into dataframe---------------------------
[2021-06-14 15:28:16,460] {logging_mixin.py:104} WARNING - /home/***/.local/lib/python3.6/site-packages/pandas/io/sql.py:1423 UserWarning: The provided table name '21N_ambassador_channel_partner_comission' is not found exactly as such in the database after writing the table, possibly due to case sensitivity issues. Consider using lower case table names.
[2021-06-14 15:28:16,461] {logging_mixin.py:104} INFO - ----------------------------------Data written into summary DB----------------------
[2021-06-14 15:28:16,461] {python.py:151} INFO - Done. Returned value was: None
[2021-06-14 15:28:16,746] {taskinstance.py:1191} INFO - Marking task as SUCCESS. dag_id=summary_db, task_id=ambassador_channel_partner_comission, execution_date=20210613T000000, start_date=20210614T152805, end_date=20210614T152816
[2021-06-14 15:28:16,957] {taskinstance.py:1245} INFO - 0 downstream tasks scheduled from follow-on schedule check
[2021-06-14 15:28:17,015] {local_task_job.py:151} INFO - Task exited with return code 0
[2021-06-14 18:33:53,323] {taskinstance.py:876} INFO - Dependencies all met for <TaskInstance: summary_db.ambassador_channel_partner_comission 2021-06-13T00:00:00+00:00 [queued]>
[2021-06-14 18:33:53,766] {taskinstance.py:876} INFO - Dependencies all met for <TaskInstance: summary_db.ambassador_channel_partner_comission 2021-06-13T00:00:00+00:00 [queued]>
[2021-06-14 18:33:53,767] {taskinstance.py:1067} INFO - 
--------------------------------------------------------------------------------
[2021-06-14 18:33:53,767] {taskinstance.py:1068} INFO - Starting attempt 1 of 2
[2021-06-14 18:33:53,767] {taskinstance.py:1069} INFO - 
--------------------------------------------------------------------------------
[2021-06-14 18:33:53,874] {taskinstance.py:1087} INFO - Executing <Task(PythonOperator): ambassador_channel_partner_comission> on 2021-06-13T00:00:00+00:00
[2021-06-14 18:33:54,048] {standard_task_runner.py:52} INFO - Started process 250 to run task
[2021-06-14 18:33:54,370] {standard_task_runner.py:76} INFO - Running: ['***', 'tasks', 'run', 'summary_db', 'ambassador_channel_partner_comission', '2021-06-13T00:00:00+00:00', '--job-id', '106', '--pool', 'default_pool', '--raw', '--subdir', 'DAGS_FOLDER/first_dag.py', '--cfg-path', '/tmp/tmpuvm2xf2y', '--error-file', '/tmp/tmpeipfw4qk']
[2021-06-14 18:33:54,371] {standard_task_runner.py:77} INFO - Job 106: Subtask ambassador_channel_partner_comission
[2021-06-14 18:33:55,878] {logging_mixin.py:104} INFO - Running <TaskInstance: summary_db.ambassador_channel_partner_comission 2021-06-13T00:00:00+00:00 [running]> on host 89c270a4555f
[2021-06-14 18:33:56,916] {taskinstance.py:1282} INFO - Exporting the following env vars:
AIRFLOW_CTX_DAG_OWNER=***
AIRFLOW_CTX_DAG_ID=summary_db
AIRFLOW_CTX_TASK_ID=ambassador_channel_partner_comission
AIRFLOW_CTX_EXECUTION_DATE=2021-06-13T00:00:00+00:00
AIRFLOW_CTX_DAG_RUN_ID=scheduled__2021-06-13T00:00:00+00:00
[2021-06-14 18:33:56,917] {logging_mixin.py:104} INFO - ------------------------------------Inside Function-----------------------------
[2021-06-14 18:34:11,905] {logging_mixin.py:104} INFO - -------------------------------Data read into dataframe---------------------------
[2021-06-14 18:34:15,986] {logging_mixin.py:104} WARNING - /home/***/.local/lib/python3.6/site-packages/pandas/io/sql.py:1423 UserWarning: The provided table name '21N_ambassador_channel_partner_comission' is not found exactly as such in the database after writing the table, possibly due to case sensitivity issues. Consider using lower case table names.
[2021-06-14 18:34:15,986] {logging_mixin.py:104} INFO - ----------------------------------Data written into summary DB----------------------
[2021-06-14 18:34:15,986] {python.py:151} INFO - Done. Returned value was: None
[2021-06-14 18:34:16,217] {taskinstance.py:1191} INFO - Marking task as SUCCESS. dag_id=summary_db, task_id=ambassador_channel_partner_comission, execution_date=20210613T000000, start_date=20210614T183353, end_date=20210614T183416
[2021-06-14 18:34:16,628] {taskinstance.py:1245} INFO - 0 downstream tasks scheduled from follow-on schedule check
[2021-06-14 18:34:16,743] {local_task_job.py:151} INFO - Task exited with return code 0
