[2021-06-16 12:57:39,589] {taskinstance.py:876} INFO - Dependencies all met for <TaskInstance: summary_db.ambassador_login 2021-06-15T00:00:00+00:00 [queued]>
[2021-06-16 12:57:39,795] {taskinstance.py:876} INFO - Dependencies all met for <TaskInstance: summary_db.ambassador_login 2021-06-15T00:00:00+00:00 [queued]>
[2021-06-16 12:57:39,795] {taskinstance.py:1067} INFO - 
--------------------------------------------------------------------------------
[2021-06-16 12:57:39,796] {taskinstance.py:1068} INFO - Starting attempt 1 of 4
[2021-06-16 12:57:39,796] {taskinstance.py:1069} INFO - 
--------------------------------------------------------------------------------
[2021-06-16 12:57:39,944] {taskinstance.py:1087} INFO - Executing <Task(PythonOperator): ambassador_login> on 2021-06-15T00:00:00+00:00
[2021-06-16 12:57:40,121] {standard_task_runner.py:52} INFO - Started process 1057 to run task
[2021-06-16 12:57:40,140] {standard_task_runner.py:76} INFO - Running: ['***', 'tasks', 'run', 'summary_db', 'ambassador_login', '2021-06-15T00:00:00+00:00', '--job-id', '179', '--pool', 'default_pool', '--raw', '--subdir', 'DAGS_FOLDER/first_dag.py', '--cfg-path', '/tmp/tmp0chpdcuu', '--error-file', '/tmp/tmplig_c219']
[2021-06-16 12:57:40,149] {standard_task_runner.py:77} INFO - Job 179: Subtask ambassador_login
[2021-06-16 12:58:26,528] {logging_mixin.py:104} INFO - Running <TaskInstance: summary_db.ambassador_login 2021-06-15T00:00:00+00:00 [running]> on host ac3e7c1eb084
[2021-06-16 12:59:03,590] {taskinstance.py:1282} INFO - Exporting the following env vars:
AIRFLOW_CTX_DAG_OWNER=***
AIRFLOW_CTX_DAG_ID=summary_db
AIRFLOW_CTX_TASK_ID=ambassador_login
AIRFLOW_CTX_EXECUTION_DATE=2021-06-15T00:00:00+00:00
AIRFLOW_CTX_DAG_RUN_ID=scheduled__2021-06-15T00:00:00+00:00
[2021-06-16 12:59:03,591] {logging_mixin.py:104} INFO - ------------------------------------Inside Function-----------------------------
[2021-06-16 12:59:17,635] {local_task_job.py:197} WARNING - State of this instance has been externally set to None. Terminating instance.
[2021-06-16 12:59:17,696] {process_utils.py:100} INFO - Sending Signals.SIGTERM to GPID 1057
[2021-06-16 12:59:25,791] {taskinstance.py:1264} ERROR - Received SIGTERM. Terminating subprocesses.
[2021-06-16 12:59:26,093] {taskinstance.py:1481} ERROR - Task failed with exception
Traceback (most recent call last):
  File "/home/airflow/.local/lib/python3.6/site-packages/sqlalchemy/pool/base.py", line 656, in __connect
    connection = pool._invoke_creator(self)
  File "/home/airflow/.local/lib/python3.6/site-packages/sqlalchemy/engine/strategies.py", line 114, in connect
    return dialect.connect(*cargs, **cparams)
  File "/home/airflow/.local/lib/python3.6/site-packages/sqlalchemy/engine/default.py", line 508, in connect
    return self.dbapi.connect(*cargs, **cparams)
  File "/home/airflow/.local/lib/python3.6/site-packages/MySQLdb/__init__.py", line 130, in Connect
    return Connection(*args, **kwargs)
  File "/home/airflow/.local/lib/python3.6/site-packages/MySQLdb/connections.py", line 185, in __init__
    super().__init__(*args, **kwargs2)
MySQLdb._exceptions.OperationalError: (2003, "Can't connect to MySQL server on '3.0.136.197:3306' (111)")

During handling of the above exception, another exception occurred:

Traceback (most recent call last):
  File "/home/airflow/.local/lib/python3.6/site-packages/airflow/models/taskinstance.py", line 1137, in _run_raw_task
    self._prepare_and_execute_task_with_callbacks(context, task)
  File "/home/airflow/.local/lib/python3.6/site-packages/airflow/models/taskinstance.py", line 1311, in _prepare_and_execute_task_with_callbacks
    result = self._execute_task(context, task_copy)
  File "/home/airflow/.local/lib/python3.6/site-packages/airflow/models/taskinstance.py", line 1341, in _execute_task
    result = task_copy.execute(context=context)
  File "/home/airflow/.local/lib/python3.6/site-packages/airflow/operators/python.py", line 150, in execute
    return_value = self.execute_callable()
  File "/home/airflow/.local/lib/python3.6/site-packages/airflow/operators/python.py", line 161, in execute_callable
    return self.python_callable(*self.op_args, **self.op_kwargs)
  File "/opt/airflow/dags/first_dag.py", line 141, in ambassador_login
    con='mysql+mysqldb://'+REPLICA_DB_USER+':'+REPLICA_DB_PASSWORD+'@'+REPLICA_DB_HOST+':'+REPLICA_DB_PORT+'/'+REPLICA_DB+'?ssl_mode=DISABLED')
  File "/home/airflow/.local/lib/python3.6/site-packages/pandas/io/sql.py", line 383, in read_sql_query
    chunksize=chunksize,
  File "/home/airflow/.local/lib/python3.6/site-packages/pandas/io/sql.py", line 1295, in read_query
    result = self.execute(*args)
  File "/home/airflow/.local/lib/python3.6/site-packages/pandas/io/sql.py", line 1162, in execute
    *args, **kwargs
  File "/home/airflow/.local/lib/python3.6/site-packages/sqlalchemy/engine/base.py", line 2234, in execute
    connection = self._contextual_connect(close_with_result=True)
  File "/home/airflow/.local/lib/python3.6/site-packages/sqlalchemy/engine/base.py", line 2302, in _contextual_connect
    self._wrap_pool_connect(self.pool.connect, None),
  File "/home/airflow/.local/lib/python3.6/site-packages/sqlalchemy/engine/base.py", line 2336, in _wrap_pool_connect
    return fn()
  File "/home/airflow/.local/lib/python3.6/site-packages/sqlalchemy/pool/base.py", line 364, in connect
    return _ConnectionFairy._checkout(self)
  File "/home/airflow/.local/lib/python3.6/site-packages/sqlalchemy/pool/base.py", line 778, in _checkout
    fairy = _ConnectionRecord.checkout(pool)
  File "/home/airflow/.local/lib/python3.6/site-packages/sqlalchemy/pool/base.py", line 495, in checkout
    rec = pool._do_get()
  File "/home/airflow/.local/lib/python3.6/site-packages/sqlalchemy/pool/impl.py", line 140, in _do_get
    self._dec_overflow()
  File "/home/airflow/.local/lib/python3.6/site-packages/sqlalchemy/util/langhelpers.py", line 70, in __exit__
    with_traceback=exc_tb,
  File "/home/airflow/.local/lib/python3.6/site-packages/sqlalchemy/util/compat.py", line 182, in raise_
    raise exception
  File "/home/airflow/.local/lib/python3.6/site-packages/sqlalchemy/pool/impl.py", line 137, in _do_get
    return self._create_connection()
  File "/home/airflow/.local/lib/python3.6/site-packages/sqlalchemy/pool/base.py", line 309, in _create_connection
    return _ConnectionRecord(self)
  File "/home/airflow/.local/lib/python3.6/site-packages/sqlalchemy/pool/base.py", line 440, in __init__
    self.__connect(first_connect_check=True)
  File "/home/airflow/.local/lib/python3.6/site-packages/sqlalchemy/pool/base.py", line 656, in __connect
    connection = pool._invoke_creator(self)
  File "/home/airflow/.local/lib/python3.6/site-packages/airflow/models/taskinstance.py", line 1266, in signal_handler
    raise AirflowException("Task received SIGTERM signal")
airflow.exceptions.AirflowException: Task received SIGTERM signal
[2021-06-16 12:59:26,138] {taskinstance.py:1531} INFO - Marking task as UP_FOR_RETRY. dag_id=summary_db, task_id=ambassador_login, execution_date=20210615T000000, start_date=20210616T125739, end_date=20210616T125926
[2021-06-16 12:59:26,552] {process_utils.py:66} INFO - Process psutil.Process(pid=1057, status='terminated', exitcode=1, started='12:57:39') (1057) terminated with exit code 1
