[2021-06-14 12:54:09,289] {taskinstance.py:876} INFO - Dependencies all met for <TaskInstance: summary_db.ambassador_channel_partner_tied 2021-06-13T00:00:00+00:00 [queued]>
[2021-06-14 12:54:09,415] {taskinstance.py:876} INFO - Dependencies all met for <TaskInstance: summary_db.ambassador_channel_partner_tied 2021-06-13T00:00:00+00:00 [queued]>
[2021-06-14 12:54:09,416] {taskinstance.py:1067} INFO - 
--------------------------------------------------------------------------------
[2021-06-14 12:54:09,416] {taskinstance.py:1068} INFO - Starting attempt 2 of 2
[2021-06-14 12:54:09,417] {taskinstance.py:1069} INFO - 
--------------------------------------------------------------------------------
[2021-06-14 12:54:09,477] {taskinstance.py:1087} INFO - Executing <Task(PythonOperator): ambassador_channel_partner_tied> on 2021-06-13T00:00:00+00:00
[2021-06-14 12:54:09,512] {standard_task_runner.py:52} INFO - Started process 668 to run task
[2021-06-14 12:54:09,530] {standard_task_runner.py:76} INFO - Running: ['***', 'tasks', 'run', 'summary_db', 'ambassador_channel_partner_tied', '2021-06-13T00:00:00+00:00', '--job-id', '61', '--pool', 'default_pool', '--raw', '--subdir', 'DAGS_FOLDER/first_dag.py', '--cfg-path', '/tmp/tmpug83n2r_', '--error-file', '/tmp/tmpmhrm2jf9']
[2021-06-14 12:54:09,531] {standard_task_runner.py:77} INFO - Job 61: Subtask ambassador_channel_partner_tied
[2021-06-14 12:54:09,784] {logging_mixin.py:104} INFO - Running <TaskInstance: summary_db.ambassador_channel_partner_tied 2021-06-13T00:00:00+00:00 [running]> on host 7874826b9cd7
[2021-06-14 12:54:10,051] {taskinstance.py:1282} INFO - Exporting the following env vars:
AIRFLOW_CTX_DAG_OWNER=***
AIRFLOW_CTX_DAG_ID=summary_db
AIRFLOW_CTX_TASK_ID=ambassador_channel_partner_tied
AIRFLOW_CTX_EXECUTION_DATE=2021-06-13T00:00:00+00:00
AIRFLOW_CTX_DAG_RUN_ID=scheduled__2021-06-13T00:00:00+00:00
[2021-06-14 12:54:10,053] {logging_mixin.py:104} INFO - ------------------------------------Inside Function-----------------------------
[2021-06-14 12:54:12,751] {logging_mixin.py:104} INFO - -------------------------------Data read into dataframe---------------------------
[2021-06-14 12:54:13,016] {taskinstance.py:1481} ERROR - Task failed with exception
Traceback (most recent call last):
  File "/home/airflow/.local/lib/python3.6/site-packages/airflow/models/taskinstance.py", line 1137, in _run_raw_task
    self._prepare_and_execute_task_with_callbacks(context, task)
  File "/home/airflow/.local/lib/python3.6/site-packages/airflow/models/taskinstance.py", line 1311, in _prepare_and_execute_task_with_callbacks
    result = self._execute_task(context, task_copy)
  File "/home/airflow/.local/lib/python3.6/site-packages/airflow/models/taskinstance.py", line 1341, in _execute_task
    result = task_copy.execute(context=context)
  File "/home/airflow/.local/lib/python3.6/site-packages/airflow/operators/python.py", line 150, in execute
    return_value = self.execute_callable()
  File "/home/airflow/.local/lib/python3.6/site-packages/airflow/operators/python.py", line 161, in execute_callable
    return self.python_callable(*self.op_args, **self.op_kwargs)
  File "/opt/airflow/dags/first_dag.py", line 68, in ambassador_channel_partner_tied
    index=False)
  File "/home/airflow/.local/lib/python3.6/site-packages/pandas/core/generic.py", line 2615, in to_sql
    method=method,
  File "/home/airflow/.local/lib/python3.6/site-packages/pandas/io/sql.py", line 598, in to_sql
    method=method,
  File "/home/airflow/.local/lib/python3.6/site-packages/pandas/io/sql.py", line 1393, in to_sql
    table.create()
  File "/home/airflow/.local/lib/python3.6/site-packages/pandas/io/sql.py", line 725, in create
    self.pd_sql.drop_table(self.name, self.schema)
  File "/home/airflow/.local/lib/python3.6/site-packages/pandas/io/sql.py", line 1453, in drop_table
    self.meta.reflect(only=[table_name], schema=schema)
  File "/home/airflow/.local/lib/python3.6/site-packages/sqlalchemy/sql/schema.py", line 4612, in reflect
    "in %r%s: (%s)" % (bind.engine, s, ", ".join(missing))
sqlalchemy.exc.InvalidRequestError: Could not reflect: requested table(s) not available in Engine(mysql://root:***@host.docker.internal:3306/21north) schema '21north': (21N_ambassador_channel_partner_tied)
[2021-06-14 12:54:13,071] {taskinstance.py:1531} INFO - Marking task as FAILED. dag_id=summary_db, task_id=ambassador_channel_partner_tied, execution_date=20210613T000000, start_date=20210614T125409, end_date=20210614T125413
[2021-06-14 12:54:13,306] {local_task_job.py:151} INFO - Task exited with return code 1
[2021-06-14 15:33:13,499] {taskinstance.py:876} INFO - Dependencies all met for <TaskInstance: summary_db.ambassador_channel_partner_tied 2021-06-13T00:00:00+00:00 [queued]>
[2021-06-14 15:33:13,547] {taskinstance.py:876} INFO - Dependencies all met for <TaskInstance: summary_db.ambassador_channel_partner_tied 2021-06-13T00:00:00+00:00 [queued]>
[2021-06-14 15:33:13,548] {taskinstance.py:1067} INFO - 
--------------------------------------------------------------------------------
[2021-06-14 15:33:13,549] {taskinstance.py:1068} INFO - Starting attempt 2 of 2
[2021-06-14 15:33:13,550] {taskinstance.py:1069} INFO - 
--------------------------------------------------------------------------------
[2021-06-14 15:33:13,585] {taskinstance.py:1087} INFO - Executing <Task(PythonOperator): ambassador_channel_partner_tied> on 2021-06-13T00:00:00+00:00
[2021-06-14 15:33:13,607] {standard_task_runner.py:52} INFO - Started process 1068 to run task
[2021-06-14 15:33:13,620] {standard_task_runner.py:76} INFO - Running: ['***', 'tasks', 'run', 'summary_db', 'ambassador_channel_partner_tied', '2021-06-13T00:00:00+00:00', '--job-id', '96', '--pool', 'default_pool', '--raw', '--subdir', 'DAGS_FOLDER/first_dag.py', '--cfg-path', '/tmp/tmpkc059r0k', '--error-file', '/tmp/tmp2kcbl6fy']
[2021-06-14 15:33:13,621] {standard_task_runner.py:77} INFO - Job 96: Subtask ambassador_channel_partner_tied
[2021-06-14 15:33:13,777] {logging_mixin.py:104} INFO - Running <TaskInstance: summary_db.ambassador_channel_partner_tied 2021-06-13T00:00:00+00:00 [running]> on host 7874826b9cd7
[2021-06-14 15:33:13,938] {taskinstance.py:1282} INFO - Exporting the following env vars:
AIRFLOW_CTX_DAG_OWNER=***
AIRFLOW_CTX_DAG_ID=summary_db
AIRFLOW_CTX_TASK_ID=ambassador_channel_partner_tied
AIRFLOW_CTX_EXECUTION_DATE=2021-06-13T00:00:00+00:00
AIRFLOW_CTX_DAG_RUN_ID=scheduled__2021-06-13T00:00:00+00:00
[2021-06-14 15:33:13,940] {logging_mixin.py:104} INFO - ------------------------------------Inside Function-----------------------------
[2021-06-14 15:33:16,395] {logging_mixin.py:104} INFO - -------------------------------Data read into dataframe---------------------------
[2021-06-14 15:33:16,609] {taskinstance.py:1481} ERROR - Task failed with exception
Traceback (most recent call last):
  File "/home/airflow/.local/lib/python3.6/site-packages/airflow/models/taskinstance.py", line 1137, in _run_raw_task
    self._prepare_and_execute_task_with_callbacks(context, task)
  File "/home/airflow/.local/lib/python3.6/site-packages/airflow/models/taskinstance.py", line 1311, in _prepare_and_execute_task_with_callbacks
    result = self._execute_task(context, task_copy)
  File "/home/airflow/.local/lib/python3.6/site-packages/airflow/models/taskinstance.py", line 1341, in _execute_task
    result = task_copy.execute(context=context)
  File "/home/airflow/.local/lib/python3.6/site-packages/airflow/operators/python.py", line 150, in execute
    return_value = self.execute_callable()
  File "/home/airflow/.local/lib/python3.6/site-packages/airflow/operators/python.py", line 161, in execute_callable
    return self.python_callable(*self.op_args, **self.op_kwargs)
  File "/opt/airflow/dags/first_dag.py", line 70, in ambassador_channel_partner_tied
    index=False)
  File "/home/airflow/.local/lib/python3.6/site-packages/pandas/core/generic.py", line 2615, in to_sql
    method=method,
  File "/home/airflow/.local/lib/python3.6/site-packages/pandas/io/sql.py", line 598, in to_sql
    method=method,
  File "/home/airflow/.local/lib/python3.6/site-packages/pandas/io/sql.py", line 1393, in to_sql
    table.create()
  File "/home/airflow/.local/lib/python3.6/site-packages/pandas/io/sql.py", line 725, in create
    self.pd_sql.drop_table(self.name, self.schema)
  File "/home/airflow/.local/lib/python3.6/site-packages/pandas/io/sql.py", line 1453, in drop_table
    self.meta.reflect(only=[table_name], schema=schema)
  File "/home/airflow/.local/lib/python3.6/site-packages/sqlalchemy/sql/schema.py", line 4612, in reflect
    "in %r%s: (%s)" % (bind.engine, s, ", ".join(missing))
sqlalchemy.exc.InvalidRequestError: Could not reflect: requested table(s) not available in Engine(mysql://root:***@host.docker.internal:3306/21north) schema '21north': (21N_ambassador_channel_partner_tied)
[2021-06-14 15:33:16,649] {taskinstance.py:1531} INFO - Marking task as FAILED. dag_id=summary_db, task_id=ambassador_channel_partner_tied, execution_date=20210613T000000, start_date=20210614T153313, end_date=20210614T153316
[2021-06-14 15:33:16,744] {local_task_job.py:151} INFO - Task exited with return code 1
