[2021-06-08 16:53:19,999] {taskinstance.py:876} INFO - Dependencies all met for <TaskInstance: first_dag.db_conn 2021-06-07T00:00:00+00:00 [queued]>
[2021-06-08 16:53:20,032] {taskinstance.py:876} INFO - Dependencies all met for <TaskInstance: first_dag.db_conn 2021-06-07T00:00:00+00:00 [queued]>
[2021-06-08 16:53:20,032] {taskinstance.py:1067} INFO - 
--------------------------------------------------------------------------------
[2021-06-08 16:53:20,033] {taskinstance.py:1068} INFO - Starting attempt 2 of 2
[2021-06-08 16:53:20,037] {taskinstance.py:1069} INFO - 
--------------------------------------------------------------------------------
[2021-06-08 16:53:20,048] {taskinstance.py:1087} INFO - Executing <Task(MySqlOperator): db_conn> on 2021-06-07T00:00:00+00:00
[2021-06-08 16:53:20,062] {standard_task_runner.py:52} INFO - Started process 424 to run task
[2021-06-08 16:53:20,066] {standard_task_runner.py:76} INFO - Running: ['***', 'tasks', 'run', 'first_dag', 'db_conn', '2021-06-07T00:00:00+00:00', '--job-id', '8', '--pool', 'default_pool', '--raw', '--subdir', 'DAGS_FOLDER/first_dag.py', '--cfg-path', '/tmp/tmp66ubte7e', '--error-file', '/tmp/tmpkl_lotc_']
[2021-06-08 16:53:20,067] {standard_task_runner.py:77} INFO - Job 8: Subtask db_conn
[2021-06-08 16:53:20,124] {logging_mixin.py:104} INFO - Running <TaskInstance: first_dag.db_conn 2021-06-07T00:00:00+00:00 [running]> on host b504216ed7b1
[2021-06-08 16:53:20,208] {taskinstance.py:1282} INFO - Exporting the following env vars:
AIRFLOW_CTX_DAG_OWNER=***
AIRFLOW_CTX_DAG_ID=first_dag
AIRFLOW_CTX_TASK_ID=db_conn
AIRFLOW_CTX_EXECUTION_DATE=2021-06-07T00:00:00+00:00
AIRFLOW_CTX_DAG_RUN_ID=scheduled__2021-06-07T00:00:00+00:00
[2021-06-08 16:53:20,208] {mysql.py:72} INFO - Executing: SELECT * FROM 21N_ambassador_login;
[2021-06-08 16:53:20,228] {base.py:78} INFO - Using connection to: id: 21n_replica. Host: 3.0.136.197, Port: 3306, Schema: 21north, Login: yantra, Password: ***, extra: {}
[2021-06-08 16:53:41,244] {taskinstance.py:1481} ERROR - Task failed with exception
Traceback (most recent call last):
  File "/home/airflow/.local/lib/python3.6/site-packages/airflow/models/taskinstance.py", line 1137, in _run_raw_task
    self._prepare_and_execute_task_with_callbacks(context, task)
  File "/home/airflow/.local/lib/python3.6/site-packages/airflow/models/taskinstance.py", line 1311, in _prepare_and_execute_task_with_callbacks
    result = self._execute_task(context, task_copy)
  File "/home/airflow/.local/lib/python3.6/site-packages/airflow/models/taskinstance.py", line 1341, in _execute_task
    result = task_copy.execute(context=context)
  File "/home/airflow/.local/lib/python3.6/site-packages/airflow/providers/mysql/operators/mysql.py", line 74, in execute
    hook.run(self.sql, autocommit=self.autocommit, parameters=self.parameters)
  File "/home/airflow/.local/lib/python3.6/site-packages/airflow/hooks/dbapi.py", line 177, in run
    with closing(self.get_conn()) as conn:
  File "/home/airflow/.local/lib/python3.6/site-packages/airflow/providers/mysql/hooks/mysql.py", line 168, in get_conn
    return MySQLdb.connect(**conn_config)
  File "/home/airflow/.local/lib/python3.6/site-packages/MySQLdb/__init__.py", line 130, in Connect
    return Connection(*args, **kwargs)
  File "/home/airflow/.local/lib/python3.6/site-packages/MySQLdb/connections.py", line 185, in __init__
    super().__init__(*args, **kwargs2)
MySQLdb._exceptions.OperationalError: (2003, "Can't connect to MySQL server on '3.0.136.197:3306' (111)")
[2021-06-08 16:53:41,248] {taskinstance.py:1531} INFO - Marking task as FAILED. dag_id=first_dag, task_id=db_conn, execution_date=20210607T000000, start_date=20210608T165320, end_date=20210608T165341
[2021-06-08 16:53:41,300] {local_task_job.py:151} INFO - Task exited with return code 1
