[2021-06-14 12:48:59,682] {taskinstance.py:876} INFO - Dependencies all met for <TaskInstance: summary_db.ambassador_info 2021-06-13T00:00:00+00:00 [queued]>
[2021-06-14 12:49:00,068] {taskinstance.py:876} INFO - Dependencies all met for <TaskInstance: summary_db.ambassador_info 2021-06-13T00:00:00+00:00 [queued]>
[2021-06-14 12:49:00,068] {taskinstance.py:1067} INFO - 
--------------------------------------------------------------------------------
[2021-06-14 12:49:00,068] {taskinstance.py:1068} INFO - Starting attempt 1 of 2
[2021-06-14 12:49:00,068] {taskinstance.py:1069} INFO - 
--------------------------------------------------------------------------------
[2021-06-14 12:49:00,127] {taskinstance.py:1087} INFO - Executing <Task(PythonOperator): ambassador_info> on 2021-06-13T00:00:00+00:00
[2021-06-14 12:49:00,224] {standard_task_runner.py:52} INFO - Started process 372 to run task
[2021-06-14 12:49:00,482] {standard_task_runner.py:76} INFO - Running: ['***', 'tasks', 'run', 'summary_db', 'ambassador_info', '2021-06-13T00:00:00+00:00', '--job-id', '40', '--pool', 'default_pool', '--raw', '--subdir', 'DAGS_FOLDER/first_dag.py', '--cfg-path', '/tmp/tmp7s_t2s89', '--error-file', '/tmp/tmpldc7cwxj']
[2021-06-14 12:49:00,533] {standard_task_runner.py:77} INFO - Job 40: Subtask ambassador_info
[2021-06-14 12:49:01,440] {logging_mixin.py:104} INFO - Running <TaskInstance: summary_db.ambassador_info 2021-06-13T00:00:00+00:00 [running]> on host 7874826b9cd7
[2021-06-14 12:49:02,010] {taskinstance.py:1282} INFO - Exporting the following env vars:
AIRFLOW_CTX_DAG_OWNER=***
AIRFLOW_CTX_DAG_ID=summary_db
AIRFLOW_CTX_TASK_ID=ambassador_info
AIRFLOW_CTX_EXECUTION_DATE=2021-06-13T00:00:00+00:00
AIRFLOW_CTX_DAG_RUN_ID=scheduled__2021-06-13T00:00:00+00:00
[2021-06-14 12:49:02,030] {logging_mixin.py:104} INFO - ------------------------------------Inside Function-----------------------------
[2021-06-14 12:49:17,861] {logging_mixin.py:104} INFO - -------------------------------Data read into dataframe---------------------------
[2021-06-14 12:49:18,955] {taskinstance.py:1481} ERROR - Task failed with exception
Traceback (most recent call last):
  File "/home/airflow/.local/lib/python3.6/site-packages/airflow/models/taskinstance.py", line 1137, in _run_raw_task
    self._prepare_and_execute_task_with_callbacks(context, task)
  File "/home/airflow/.local/lib/python3.6/site-packages/airflow/models/taskinstance.py", line 1311, in _prepare_and_execute_task_with_callbacks
    result = self._execute_task(context, task_copy)
  File "/home/airflow/.local/lib/python3.6/site-packages/airflow/models/taskinstance.py", line 1341, in _execute_task
    result = task_copy.execute(context=context)
  File "/home/airflow/.local/lib/python3.6/site-packages/airflow/operators/python.py", line 150, in execute
    return_value = self.execute_callable()
  File "/home/airflow/.local/lib/python3.6/site-packages/airflow/operators/python.py", line 161, in execute_callable
    return self.python_callable(*self.op_args, **self.op_kwargs)
  File "/opt/airflow/dags/first_dag.py", line 87, in ambassador_info
    index=False)
  File "/home/airflow/.local/lib/python3.6/site-packages/pandas/core/generic.py", line 2615, in to_sql
    method=method,
  File "/home/airflow/.local/lib/python3.6/site-packages/pandas/io/sql.py", line 598, in to_sql
    method=method,
  File "/home/airflow/.local/lib/python3.6/site-packages/pandas/io/sql.py", line 1393, in to_sql
    table.create()
  File "/home/airflow/.local/lib/python3.6/site-packages/pandas/io/sql.py", line 725, in create
    self.pd_sql.drop_table(self.name, self.schema)
  File "/home/airflow/.local/lib/python3.6/site-packages/pandas/io/sql.py", line 1453, in drop_table
    self.meta.reflect(only=[table_name], schema=schema)
  File "/home/airflow/.local/lib/python3.6/site-packages/sqlalchemy/sql/schema.py", line 4612, in reflect
    "in %r%s: (%s)" % (bind.engine, s, ", ".join(missing))
sqlalchemy.exc.InvalidRequestError: Could not reflect: requested table(s) not available in Engine(mysql://root:***@host.docker.internal:3306/21north) schema '21north': (21N_ambassador_info)
[2021-06-14 12:49:18,979] {taskinstance.py:1531} INFO - Marking task as UP_FOR_RETRY. dag_id=summary_db, task_id=ambassador_info, execution_date=20210613T000000, start_date=20210614T124859, end_date=20210614T124918
[2021-06-14 12:49:19,187] {local_task_job.py:151} INFO - Task exited with return code 1
[2021-06-14 15:28:06,994] {taskinstance.py:876} INFO - Dependencies all met for <TaskInstance: summary_db.ambassador_info 2021-06-13T00:00:00+00:00 [queued]>
[2021-06-14 15:28:07,257] {taskinstance.py:876} INFO - Dependencies all met for <TaskInstance: summary_db.ambassador_info 2021-06-13T00:00:00+00:00 [queued]>
[2021-06-14 15:28:07,257] {taskinstance.py:1067} INFO - 
--------------------------------------------------------------------------------
[2021-06-14 15:28:07,258] {taskinstance.py:1068} INFO - Starting attempt 1 of 2
[2021-06-14 15:28:07,258] {taskinstance.py:1069} INFO - 
--------------------------------------------------------------------------------
[2021-06-14 15:28:07,515] {taskinstance.py:1087} INFO - Executing <Task(PythonOperator): ambassador_info> on 2021-06-13T00:00:00+00:00
[2021-06-14 15:28:07,675] {standard_task_runner.py:52} INFO - Started process 800 to run task
[2021-06-14 15:28:07,704] {standard_task_runner.py:76} INFO - Running: ['***', 'tasks', 'run', 'summary_db', 'ambassador_info', '2021-06-13T00:00:00+00:00', '--job-id', '77', '--pool', 'default_pool', '--raw', '--subdir', 'DAGS_FOLDER/first_dag.py', '--cfg-path', '/tmp/tmpxeddiv52', '--error-file', '/tmp/tmpczidgvvs']
[2021-06-14 15:28:07,776] {standard_task_runner.py:77} INFO - Job 77: Subtask ambassador_info
[2021-06-14 15:28:08,635] {logging_mixin.py:104} INFO - Running <TaskInstance: summary_db.ambassador_info 2021-06-13T00:00:00+00:00 [running]> on host 7874826b9cd7
[2021-06-14 15:28:09,394] {taskinstance.py:1282} INFO - Exporting the following env vars:
AIRFLOW_CTX_DAG_OWNER=***
AIRFLOW_CTX_DAG_ID=summary_db
AIRFLOW_CTX_TASK_ID=ambassador_info
AIRFLOW_CTX_EXECUTION_DATE=2021-06-13T00:00:00+00:00
AIRFLOW_CTX_DAG_RUN_ID=scheduled__2021-06-13T00:00:00+00:00
[2021-06-14 15:28:09,402] {logging_mixin.py:104} INFO - ------------------------------------Inside Function-----------------------------
[2021-06-14 15:28:25,712] {logging_mixin.py:104} INFO - -------------------------------Data read into dataframe---------------------------
[2021-06-14 15:28:26,907] {taskinstance.py:1481} ERROR - Task failed with exception
Traceback (most recent call last):
  File "/home/airflow/.local/lib/python3.6/site-packages/airflow/models/taskinstance.py", line 1137, in _run_raw_task
    self._prepare_and_execute_task_with_callbacks(context, task)
  File "/home/airflow/.local/lib/python3.6/site-packages/airflow/models/taskinstance.py", line 1311, in _prepare_and_execute_task_with_callbacks
    result = self._execute_task(context, task_copy)
  File "/home/airflow/.local/lib/python3.6/site-packages/airflow/models/taskinstance.py", line 1341, in _execute_task
    result = task_copy.execute(context=context)
  File "/home/airflow/.local/lib/python3.6/site-packages/airflow/operators/python.py", line 150, in execute
    return_value = self.execute_callable()
  File "/home/airflow/.local/lib/python3.6/site-packages/airflow/operators/python.py", line 161, in execute_callable
    return self.python_callable(*self.op_args, **self.op_kwargs)
  File "/opt/airflow/dags/first_dag.py", line 89, in ambassador_info
    index=False)
  File "/home/airflow/.local/lib/python3.6/site-packages/pandas/core/generic.py", line 2615, in to_sql
    method=method,
  File "/home/airflow/.local/lib/python3.6/site-packages/pandas/io/sql.py", line 598, in to_sql
    method=method,
  File "/home/airflow/.local/lib/python3.6/site-packages/pandas/io/sql.py", line 1393, in to_sql
    table.create()
  File "/home/airflow/.local/lib/python3.6/site-packages/pandas/io/sql.py", line 725, in create
    self.pd_sql.drop_table(self.name, self.schema)
  File "/home/airflow/.local/lib/python3.6/site-packages/pandas/io/sql.py", line 1453, in drop_table
    self.meta.reflect(only=[table_name], schema=schema)
  File "/home/airflow/.local/lib/python3.6/site-packages/sqlalchemy/sql/schema.py", line 4612, in reflect
    "in %r%s: (%s)" % (bind.engine, s, ", ".join(missing))
sqlalchemy.exc.InvalidRequestError: Could not reflect: requested table(s) not available in Engine(mysql://root:***@host.docker.internal:3306/21north) schema '21north': (21N_ambassador_info)
[2021-06-14 15:28:26,972] {taskinstance.py:1531} INFO - Marking task as UP_FOR_RETRY. dag_id=summary_db, task_id=ambassador_info, execution_date=20210613T000000, start_date=20210614T152807, end_date=20210614T152826
[2021-06-14 15:28:27,295] {local_task_job.py:151} INFO - Task exited with return code 1
[2021-06-14 18:33:55,643] {taskinstance.py:876} INFO - Dependencies all met for <TaskInstance: summary_db.ambassador_info 2021-06-13T00:00:00+00:00 [queued]>
[2021-06-14 18:33:55,953] {taskinstance.py:876} INFO - Dependencies all met for <TaskInstance: summary_db.ambassador_info 2021-06-13T00:00:00+00:00 [queued]>
[2021-06-14 18:33:55,953] {taskinstance.py:1067} INFO - 
--------------------------------------------------------------------------------
[2021-06-14 18:33:55,954] {taskinstance.py:1068} INFO - Starting attempt 1 of 2
[2021-06-14 18:33:55,954] {taskinstance.py:1069} INFO - 
--------------------------------------------------------------------------------
[2021-06-14 18:33:56,261] {taskinstance.py:1087} INFO - Executing <Task(PythonOperator): ambassador_info> on 2021-06-13T00:00:00+00:00
[2021-06-14 18:33:56,625] {standard_task_runner.py:52} INFO - Started process 261 to run task
[2021-06-14 18:33:56,555] {standard_task_runner.py:76} INFO - Running: ['***', 'tasks', 'run', 'summary_db', 'ambassador_info', '2021-06-13T00:00:00+00:00', '--job-id', '113', '--pool', 'default_pool', '--raw', '--subdir', 'DAGS_FOLDER/first_dag.py', '--cfg-path', '/tmp/tmpbqc6ngkb', '--error-file', '/tmp/tmp1jqdc4j0']
[2021-06-14 18:33:56,822] {standard_task_runner.py:77} INFO - Job 113: Subtask ambassador_info
[2021-06-14 18:33:58,620] {logging_mixin.py:104} INFO - Running <TaskInstance: summary_db.ambassador_info 2021-06-13T00:00:00+00:00 [running]> on host 89c270a4555f
[2021-06-14 18:33:59,508] {taskinstance.py:1282} INFO - Exporting the following env vars:
AIRFLOW_CTX_DAG_OWNER=***
AIRFLOW_CTX_DAG_ID=summary_db
AIRFLOW_CTX_TASK_ID=ambassador_info
AIRFLOW_CTX_EXECUTION_DATE=2021-06-13T00:00:00+00:00
AIRFLOW_CTX_DAG_RUN_ID=scheduled__2021-06-13T00:00:00+00:00
[2021-06-14 18:33:59,536] {logging_mixin.py:104} INFO - ------------------------------------Inside Function-----------------------------
[2021-06-14 18:34:29,842] {logging_mixin.py:104} INFO - -------------------------------Data read into dataframe---------------------------
[2021-06-14 18:35:03,937] {logging_mixin.py:104} INFO - ----------------------------------Data written into summary DB----------------------
[2021-06-14 18:35:03,952] {python.py:151} INFO - Done. Returned value was: None
[2021-06-14 18:35:03,981] {taskinstance.py:1191} INFO - Marking task as SUCCESS. dag_id=summary_db, task_id=ambassador_info, execution_date=20210613T000000, start_date=20210614T183355, end_date=20210614T183503
[2021-06-14 18:35:04,065] {taskinstance.py:1245} INFO - 0 downstream tasks scheduled from follow-on schedule check
[2021-06-14 18:35:04,152] {local_task_job.py:151} INFO - Task exited with return code 0
