[2021-06-14 12:54:20,961] {taskinstance.py:876} INFO - Dependencies all met for <TaskInstance: summary_db.ambassador_info 2021-06-13T00:00:00+00:00 [queued]>
[2021-06-14 12:54:20,994] {taskinstance.py:876} INFO - Dependencies all met for <TaskInstance: summary_db.ambassador_info 2021-06-13T00:00:00+00:00 [queued]>
[2021-06-14 12:54:20,994] {taskinstance.py:1067} INFO - 
--------------------------------------------------------------------------------
[2021-06-14 12:54:20,994] {taskinstance.py:1068} INFO - Starting attempt 2 of 2
[2021-06-14 12:54:20,994] {taskinstance.py:1069} INFO - 
--------------------------------------------------------------------------------
[2021-06-14 12:54:21,012] {taskinstance.py:1087} INFO - Executing <Task(PythonOperator): ambassador_info> on 2021-06-13T00:00:00+00:00
[2021-06-14 12:54:21,023] {standard_task_runner.py:52} INFO - Started process 676 to run task
[2021-06-14 12:54:21,028] {standard_task_runner.py:76} INFO - Running: ['***', 'tasks', 'run', 'summary_db', 'ambassador_info', '2021-06-13T00:00:00+00:00', '--job-id', '65', '--pool', 'default_pool', '--raw', '--subdir', 'DAGS_FOLDER/first_dag.py', '--cfg-path', '/tmp/tmp7kz87ehh', '--error-file', '/tmp/tmpxfio9sh6']
[2021-06-14 12:54:21,029] {standard_task_runner.py:77} INFO - Job 65: Subtask ambassador_info
[2021-06-14 12:54:21,093] {logging_mixin.py:104} INFO - Running <TaskInstance: summary_db.ambassador_info 2021-06-13T00:00:00+00:00 [running]> on host 7874826b9cd7
[2021-06-14 12:54:21,170] {taskinstance.py:1282} INFO - Exporting the following env vars:
AIRFLOW_CTX_DAG_OWNER=***
AIRFLOW_CTX_DAG_ID=summary_db
AIRFLOW_CTX_TASK_ID=ambassador_info
AIRFLOW_CTX_EXECUTION_DATE=2021-06-13T00:00:00+00:00
AIRFLOW_CTX_DAG_RUN_ID=scheduled__2021-06-13T00:00:00+00:00
[2021-06-14 12:54:21,171] {logging_mixin.py:104} INFO - ------------------------------------Inside Function-----------------------------
[2021-06-14 12:54:28,326] {logging_mixin.py:104} INFO - -------------------------------Data read into dataframe---------------------------
[2021-06-14 12:54:28,485] {taskinstance.py:1481} ERROR - Task failed with exception
Traceback (most recent call last):
  File "/home/airflow/.local/lib/python3.6/site-packages/airflow/models/taskinstance.py", line 1137, in _run_raw_task
    self._prepare_and_execute_task_with_callbacks(context, task)
  File "/home/airflow/.local/lib/python3.6/site-packages/airflow/models/taskinstance.py", line 1311, in _prepare_and_execute_task_with_callbacks
    result = self._execute_task(context, task_copy)
  File "/home/airflow/.local/lib/python3.6/site-packages/airflow/models/taskinstance.py", line 1341, in _execute_task
    result = task_copy.execute(context=context)
  File "/home/airflow/.local/lib/python3.6/site-packages/airflow/operators/python.py", line 150, in execute
    return_value = self.execute_callable()
  File "/home/airflow/.local/lib/python3.6/site-packages/airflow/operators/python.py", line 161, in execute_callable
    return self.python_callable(*self.op_args, **self.op_kwargs)
  File "/opt/airflow/dags/first_dag.py", line 87, in ambassador_info
    index=False)
  File "/home/airflow/.local/lib/python3.6/site-packages/pandas/core/generic.py", line 2615, in to_sql
    method=method,
  File "/home/airflow/.local/lib/python3.6/site-packages/pandas/io/sql.py", line 598, in to_sql
    method=method,
  File "/home/airflow/.local/lib/python3.6/site-packages/pandas/io/sql.py", line 1393, in to_sql
    table.create()
  File "/home/airflow/.local/lib/python3.6/site-packages/pandas/io/sql.py", line 725, in create
    self.pd_sql.drop_table(self.name, self.schema)
  File "/home/airflow/.local/lib/python3.6/site-packages/pandas/io/sql.py", line 1453, in drop_table
    self.meta.reflect(only=[table_name], schema=schema)
  File "/home/airflow/.local/lib/python3.6/site-packages/sqlalchemy/sql/schema.py", line 4612, in reflect
    "in %r%s: (%s)" % (bind.engine, s, ", ".join(missing))
sqlalchemy.exc.InvalidRequestError: Could not reflect: requested table(s) not available in Engine(mysql://root:***@host.docker.internal:3306/21north) schema '21north': (21N_ambassador_info)
[2021-06-14 12:54:28,491] {taskinstance.py:1531} INFO - Marking task as FAILED. dag_id=summary_db, task_id=ambassador_info, execution_date=20210613T000000, start_date=20210614T125420, end_date=20210614T125428
[2021-06-14 12:54:28,550] {local_task_job.py:151} INFO - Task exited with return code 1
[2021-06-14 15:33:29,044] {taskinstance.py:876} INFO - Dependencies all met for <TaskInstance: summary_db.ambassador_info 2021-06-13T00:00:00+00:00 [queued]>
[2021-06-14 15:33:29,073] {taskinstance.py:876} INFO - Dependencies all met for <TaskInstance: summary_db.ambassador_info 2021-06-13T00:00:00+00:00 [queued]>
[2021-06-14 15:33:29,073] {taskinstance.py:1067} INFO - 
--------------------------------------------------------------------------------
[2021-06-14 15:33:29,073] {taskinstance.py:1068} INFO - Starting attempt 2 of 2
[2021-06-14 15:33:29,073] {taskinstance.py:1069} INFO - 
--------------------------------------------------------------------------------
[2021-06-14 15:33:29,098] {taskinstance.py:1087} INFO - Executing <Task(PythonOperator): ambassador_info> on 2021-06-13T00:00:00+00:00
[2021-06-14 15:33:29,112] {standard_task_runner.py:52} INFO - Started process 1087 to run task
[2021-06-14 15:33:29,119] {standard_task_runner.py:76} INFO - Running: ['***', 'tasks', 'run', 'summary_db', 'ambassador_info', '2021-06-13T00:00:00+00:00', '--job-id', '99', '--pool', 'default_pool', '--raw', '--subdir', 'DAGS_FOLDER/first_dag.py', '--cfg-path', '/tmp/tmp1y8l8ami', '--error-file', '/tmp/tmpnr7pl4um']
[2021-06-14 15:33:29,120] {standard_task_runner.py:77} INFO - Job 99: Subtask ambassador_info
[2021-06-14 15:33:29,198] {logging_mixin.py:104} INFO - Running <TaskInstance: summary_db.ambassador_info 2021-06-13T00:00:00+00:00 [running]> on host 7874826b9cd7
[2021-06-14 15:33:29,381] {taskinstance.py:1282} INFO - Exporting the following env vars:
AIRFLOW_CTX_DAG_OWNER=***
AIRFLOW_CTX_DAG_ID=summary_db
AIRFLOW_CTX_TASK_ID=ambassador_info
AIRFLOW_CTX_EXECUTION_DATE=2021-06-13T00:00:00+00:00
AIRFLOW_CTX_DAG_RUN_ID=scheduled__2021-06-13T00:00:00+00:00
[2021-06-14 15:33:29,382] {logging_mixin.py:104} INFO - ------------------------------------Inside Function-----------------------------
[2021-06-14 15:33:37,856] {logging_mixin.py:104} INFO - -------------------------------Data read into dataframe---------------------------
[2021-06-14 15:33:38,372] {taskinstance.py:1481} ERROR - Task failed with exception
Traceback (most recent call last):
  File "/home/airflow/.local/lib/python3.6/site-packages/airflow/models/taskinstance.py", line 1137, in _run_raw_task
    self._prepare_and_execute_task_with_callbacks(context, task)
  File "/home/airflow/.local/lib/python3.6/site-packages/airflow/models/taskinstance.py", line 1311, in _prepare_and_execute_task_with_callbacks
    result = self._execute_task(context, task_copy)
  File "/home/airflow/.local/lib/python3.6/site-packages/airflow/models/taskinstance.py", line 1341, in _execute_task
    result = task_copy.execute(context=context)
  File "/home/airflow/.local/lib/python3.6/site-packages/airflow/operators/python.py", line 150, in execute
    return_value = self.execute_callable()
  File "/home/airflow/.local/lib/python3.6/site-packages/airflow/operators/python.py", line 161, in execute_callable
    return self.python_callable(*self.op_args, **self.op_kwargs)
  File "/opt/airflow/dags/first_dag.py", line 89, in ambassador_info
    index=False)
  File "/home/airflow/.local/lib/python3.6/site-packages/pandas/core/generic.py", line 2615, in to_sql
    method=method,
  File "/home/airflow/.local/lib/python3.6/site-packages/pandas/io/sql.py", line 598, in to_sql
    method=method,
  File "/home/airflow/.local/lib/python3.6/site-packages/pandas/io/sql.py", line 1393, in to_sql
    table.create()
  File "/home/airflow/.local/lib/python3.6/site-packages/pandas/io/sql.py", line 725, in create
    self.pd_sql.drop_table(self.name, self.schema)
  File "/home/airflow/.local/lib/python3.6/site-packages/pandas/io/sql.py", line 1453, in drop_table
    self.meta.reflect(only=[table_name], schema=schema)
  File "/home/airflow/.local/lib/python3.6/site-packages/sqlalchemy/sql/schema.py", line 4612, in reflect
    "in %r%s: (%s)" % (bind.engine, s, ", ".join(missing))
sqlalchemy.exc.InvalidRequestError: Could not reflect: requested table(s) not available in Engine(mysql://root:***@host.docker.internal:3306/21north) schema '21north': (21N_ambassador_info)
[2021-06-14 15:33:38,407] {taskinstance.py:1531} INFO - Marking task as FAILED. dag_id=summary_db, task_id=ambassador_info, execution_date=20210613T000000, start_date=20210614T153329, end_date=20210614T153338
[2021-06-14 15:33:38,590] {local_task_job.py:151} INFO - Task exited with return code 1
