[2021-06-14 12:49:20,524] {taskinstance.py:876} INFO - Dependencies all met for <TaskInstance: summary_db.slot_tracker 2021-06-13T00:00:00+00:00 [queued]>
[2021-06-14 12:49:20,597] {taskinstance.py:876} INFO - Dependencies all met for <TaskInstance: summary_db.slot_tracker 2021-06-13T00:00:00+00:00 [queued]>
[2021-06-14 12:49:20,601] {taskinstance.py:1067} INFO - 
--------------------------------------------------------------------------------
[2021-06-14 12:49:20,602] {taskinstance.py:1068} INFO - Starting attempt 1 of 2
[2021-06-14 12:49:20,602] {taskinstance.py:1069} INFO - 
--------------------------------------------------------------------------------
[2021-06-14 12:49:20,671] {taskinstance.py:1087} INFO - Executing <Task(PythonOperator): slot_tracker> on 2021-06-13T00:00:00+00:00
[2021-06-14 12:49:20,698] {standard_task_runner.py:52} INFO - Started process 416 to run task
[2021-06-14 12:49:20,736] {standard_task_runner.py:76} INFO - Running: ['***', 'tasks', 'run', 'summary_db', 'slot_tracker', '2021-06-13T00:00:00+00:00', '--job-id', '58', '--pool', 'default_pool', '--raw', '--subdir', 'DAGS_FOLDER/first_dag.py', '--cfg-path', '/tmp/tmpasxiarbr', '--error-file', '/tmp/tmpcao1vdkh']
[2021-06-14 12:49:20,742] {standard_task_runner.py:77} INFO - Job 58: Subtask slot_tracker
[2021-06-14 12:49:21,162] {logging_mixin.py:104} INFO - Running <TaskInstance: summary_db.slot_tracker 2021-06-13T00:00:00+00:00 [running]> on host 7874826b9cd7
[2021-06-14 12:49:21,648] {taskinstance.py:1282} INFO - Exporting the following env vars:
AIRFLOW_CTX_DAG_OWNER=***
AIRFLOW_CTX_DAG_ID=summary_db
AIRFLOW_CTX_TASK_ID=slot_tracker
AIRFLOW_CTX_EXECUTION_DATE=2021-06-13T00:00:00+00:00
AIRFLOW_CTX_DAG_RUN_ID=scheduled__2021-06-13T00:00:00+00:00
[2021-06-14 12:49:21,649] {logging_mixin.py:104} INFO - ------------------------------------Inside Function-----------------------------
[2021-06-14 12:50:01,783] {logging_mixin.py:104} INFO - -------------------------------Data read into dataframe---------------------------
[2021-06-14 12:50:01,805] {logging_mixin.py:104} WARNING - /home/***/.local/lib/python3.6/site-packages/pandas/core/generic.py:2615 UserWarning: the 'timedelta' type is not supported, and will be written as integer values (ns frequency) to the database.
[2021-06-14 12:50:02,048] {taskinstance.py:1481} ERROR - Task failed with exception
Traceback (most recent call last):
  File "/home/airflow/.local/lib/python3.6/site-packages/sqlalchemy/engine/base.py", line 1257, in _execute_context
    cursor, statement, parameters, context
  File "/home/airflow/.local/lib/python3.6/site-packages/sqlalchemy/dialects/mysql/mysqldb.py", line 148, in do_executemany
    rowcount = cursor.executemany(statement, parameters)
  File "/home/airflow/.local/lib/python3.6/site-packages/MySQLdb/cursors.py", line 236, in executemany
    self._get_db().encoding,
  File "/home/airflow/.local/lib/python3.6/site-packages/MySQLdb/cursors.py", line 261, in _do_execute_many
    rows += self.execute(sql + postfix)
  File "/home/airflow/.local/lib/python3.6/site-packages/MySQLdb/cursors.py", line 206, in execute
    res = self._query(query)
  File "/home/airflow/.local/lib/python3.6/site-packages/MySQLdb/cursors.py", line 319, in _query
    db.query(q)
  File "/home/airflow/.local/lib/python3.6/site-packages/MySQLdb/connections.py", line 259, in query
    _mysql.connection.query(self, query)
MySQLdb._exceptions.OperationalError: (1292, "Incorrect time value: '36000000000000' for column 'slot_hour' at row 1")

The above exception was the direct cause of the following exception:

Traceback (most recent call last):
  File "/home/airflow/.local/lib/python3.6/site-packages/airflow/models/taskinstance.py", line 1137, in _run_raw_task
    self._prepare_and_execute_task_with_callbacks(context, task)
  File "/home/airflow/.local/lib/python3.6/site-packages/airflow/models/taskinstance.py", line 1311, in _prepare_and_execute_task_with_callbacks
    result = self._execute_task(context, task_copy)
  File "/home/airflow/.local/lib/python3.6/site-packages/airflow/models/taskinstance.py", line 1341, in _execute_task
    result = task_copy.execute(context=context)
  File "/home/airflow/.local/lib/python3.6/site-packages/airflow/operators/python.py", line 150, in execute
    return_value = self.execute_callable()
  File "/home/airflow/.local/lib/python3.6/site-packages/airflow/operators/python.py", line 161, in execute_callable
    return self.python_callable(*self.op_args, **self.op_kwargs)
  File "/opt/airflow/dags/first_dag.py", line 485, in slot_tracker
    index=False)
  File "/home/airflow/.local/lib/python3.6/site-packages/pandas/core/generic.py", line 2615, in to_sql
    method=method,
  File "/home/airflow/.local/lib/python3.6/site-packages/pandas/io/sql.py", line 598, in to_sql
    method=method,
  File "/home/airflow/.local/lib/python3.6/site-packages/pandas/io/sql.py", line 1406, in to_sql
    raise err
  File "/home/airflow/.local/lib/python3.6/site-packages/pandas/io/sql.py", line 1398, in to_sql
    table.insert(chunksize, method=method)
  File "/home/airflow/.local/lib/python3.6/site-packages/pandas/io/sql.py", line 830, in insert
    exec_insert(conn, keys, chunk_iter)
  File "/home/airflow/.local/lib/python3.6/site-packages/pandas/io/sql.py", line 747, in _execute_insert
    conn.execute(self.table.insert(), data)
  File "/home/airflow/.local/lib/python3.6/site-packages/sqlalchemy/engine/base.py", line 1011, in execute
    return meth(self, multiparams, params)
  File "/home/airflow/.local/lib/python3.6/site-packages/sqlalchemy/sql/elements.py", line 298, in _execute_on_connection
    return connection._execute_clauseelement(self, multiparams, params)
  File "/home/airflow/.local/lib/python3.6/site-packages/sqlalchemy/engine/base.py", line 1130, in _execute_clauseelement
    distilled_params,
  File "/home/airflow/.local/lib/python3.6/site-packages/sqlalchemy/engine/base.py", line 1317, in _execute_context
    e, statement, parameters, cursor, context
  File "/home/airflow/.local/lib/python3.6/site-packages/sqlalchemy/engine/base.py", line 1511, in _handle_dbapi_exception
    sqlalchemy_exception, with_traceback=exc_info[2], from_=e
  File "/home/airflow/.local/lib/python3.6/site-packages/sqlalchemy/util/compat.py", line 182, in raise_
    raise exception
  File "/home/airflow/.local/lib/python3.6/site-packages/sqlalchemy/engine/base.py", line 1257, in _execute_context
    cursor, statement, parameters, context
  File "/home/airflow/.local/lib/python3.6/site-packages/sqlalchemy/dialects/mysql/mysqldb.py", line 148, in do_executemany
    rowcount = cursor.executemany(statement, parameters)
  File "/home/airflow/.local/lib/python3.6/site-packages/MySQLdb/cursors.py", line 236, in executemany
    self._get_db().encoding,
  File "/home/airflow/.local/lib/python3.6/site-packages/MySQLdb/cursors.py", line 261, in _do_execute_many
    rows += self.execute(sql + postfix)
  File "/home/airflow/.local/lib/python3.6/site-packages/MySQLdb/cursors.py", line 206, in execute
    res = self._query(query)
  File "/home/airflow/.local/lib/python3.6/site-packages/MySQLdb/cursors.py", line 319, in _query
    db.query(q)
  File "/home/airflow/.local/lib/python3.6/site-packages/MySQLdb/connections.py", line 259, in query
    _mysql.connection.query(self, query)
sqlalchemy.exc.OperationalError: (MySQLdb._exceptions.OperationalError) (1292, "Incorrect time value: '36000000000000' for column 'slot_hour' at row 1")
[SQL: INSERT INTO `21north`.`21N_slot_tracker` (id, creationdatetime, slot_hour, slot_count, cityid, queuetime, type_of_booking, total_slots, queueid) VALUES (%s, %s, %s, %s, %s, %s, %s, %s, %s)]
[parameters: ((447282, datetime.datetime(2021, 6, 13, 18, 19, 50), 36000000000000, 29, 148, datetime.datetime(2021, 6, 14, 10, 0), 0, 68, 1635049), (447283, datetime.datetime(2021, 6, 13, 18, 22, 38), 36000000000000, 20, 72, datetime.datetime(2021, 6, 14, 10, 0), 0, 27, 1635050), (447284, datetime.datetime(2021, 6, 13, 18, 24, 30), 39600000000000, 55, 148, datetime.datetime(2021, 6, 14, 11, 0), 0, 68, 1635051), (447285, datetime.datetime(2021, 6, 13, 18, 27, 29), 32400000000000, 4, 81, datetime.datetime(2021, 6, 14, 9, 0), 0, 5, 1635052), (447286, datetime.datetime(2021, 6, 13, 18, 35, 52), 32400000000000, 3, 81, datetime.datetime(2021, 6, 14, 9, 0), 0, 5, 1635053), (447287, datetime.datetime(2021, 6, 13, 18, 44, 23), 36000000000000, 7, 64, datetime.datetime(2021, 6, 14, 10, 0), 0, 11, 1635055), (447288, datetime.datetime(2021, 6, 13, 18, 47, 24), 32400000000000, 5, 174, datetime.datetime(2021, 6, 14, 9, 0), 0, 18, 1635056), (447289, datetime.datetime(2021, 6, 13, 18, 49, 4), 28800000000000, 26, 175, datetime.datetime(2021, 6, 14, 8, 0), 1, 26, 1635057)  ... displaying 10 of 722 total bound parameter sets ...  (448002, datetime.datetime(2021, 6, 14, 14, 35, 17), 32400000000000, 2, 176, datetime.datetime(2021, 6, 15, 9, 0), 0, 8, 1635980), (448003, datetime.datetime(2021, 6, 14, 14, 35, 27), 57600000000000, 60, 148, datetime.datetime(2021, 6, 14, 16, 0), 1, 68, 1635981))]
(Background on this error at: http://sqlalche.me/e/13/e3q8)
[2021-06-14 12:50:02,080] {taskinstance.py:1531} INFO - Marking task as UP_FOR_RETRY. dag_id=summary_db, task_id=slot_tracker, execution_date=20210613T000000, start_date=20210614T124920, end_date=20210614T125002
[2021-06-14 12:50:02,170] {local_task_job.py:151} INFO - Task exited with return code 1
[2021-06-14 15:28:36,541] {taskinstance.py:876} INFO - Dependencies all met for <TaskInstance: summary_db.slot_tracker 2021-06-13T00:00:00+00:00 [queued]>
[2021-06-14 15:28:36,776] {taskinstance.py:876} INFO - Dependencies all met for <TaskInstance: summary_db.slot_tracker 2021-06-13T00:00:00+00:00 [queued]>
[2021-06-14 15:28:36,777] {taskinstance.py:1067} INFO - 
--------------------------------------------------------------------------------
[2021-06-14 15:28:36,778] {taskinstance.py:1068} INFO - Starting attempt 1 of 2
[2021-06-14 15:28:36,779] {taskinstance.py:1069} INFO - 
--------------------------------------------------------------------------------
[2021-06-14 15:28:37,150] {taskinstance.py:1087} INFO - Executing <Task(PythonOperator): slot_tracker> on 2021-06-13T00:00:00+00:00
[2021-06-14 15:28:37,420] {standard_task_runner.py:52} INFO - Started process 845 to run task
[2021-06-14 15:28:37,437] {standard_task_runner.py:76} INFO - Running: ['***', 'tasks', 'run', 'summary_db', 'slot_tracker', '2021-06-13T00:00:00+00:00', '--job-id', '93', '--pool', 'default_pool', '--raw', '--subdir', 'DAGS_FOLDER/first_dag.py', '--cfg-path', '/tmp/tmp012zub1u', '--error-file', '/tmp/tmpy_lknbe1']
[2021-06-14 15:28:37,451] {standard_task_runner.py:77} INFO - Job 93: Subtask slot_tracker
[2021-06-14 15:28:38,335] {logging_mixin.py:104} INFO - Running <TaskInstance: summary_db.slot_tracker 2021-06-13T00:00:00+00:00 [running]> on host 7874826b9cd7
[2021-06-14 15:28:38,955] {taskinstance.py:1282} INFO - Exporting the following env vars:
AIRFLOW_CTX_DAG_OWNER=***
AIRFLOW_CTX_DAG_ID=summary_db
AIRFLOW_CTX_TASK_ID=slot_tracker
AIRFLOW_CTX_EXECUTION_DATE=2021-06-13T00:00:00+00:00
AIRFLOW_CTX_DAG_RUN_ID=scheduled__2021-06-13T00:00:00+00:00
[2021-06-14 15:28:38,964] {logging_mixin.py:104} INFO - ------------------------------------Inside Function-----------------------------
[2021-06-14 15:29:07,676] {logging_mixin.py:104} INFO - -------------------------------Data read into dataframe---------------------------
[2021-06-14 15:29:08,034] {taskinstance.py:1481} ERROR - Task failed with exception
Traceback (most recent call last):
  File "/home/airflow/.local/lib/python3.6/site-packages/sqlalchemy/engine/base.py", line 1257, in _execute_context
    cursor, statement, parameters, context
  File "/home/airflow/.local/lib/python3.6/site-packages/sqlalchemy/dialects/mysql/mysqldb.py", line 148, in do_executemany
    rowcount = cursor.executemany(statement, parameters)
  File "/home/airflow/.local/lib/python3.6/site-packages/MySQLdb/cursors.py", line 236, in executemany
    self._get_db().encoding,
  File "/home/airflow/.local/lib/python3.6/site-packages/MySQLdb/cursors.py", line 261, in _do_execute_many
    rows += self.execute(sql + postfix)
  File "/home/airflow/.local/lib/python3.6/site-packages/MySQLdb/cursors.py", line 206, in execute
    res = self._query(query)
  File "/home/airflow/.local/lib/python3.6/site-packages/MySQLdb/cursors.py", line 319, in _query
    db.query(q)
  File "/home/airflow/.local/lib/python3.6/site-packages/MySQLdb/connections.py", line 259, in query
    _mysql.connection.query(self, query)
MySQLdb._exceptions.OperationalError: (1292, "Incorrect time value: '32400000000000' for column 'slot_hour' at row 1")

The above exception was the direct cause of the following exception:

Traceback (most recent call last):
  File "/home/airflow/.local/lib/python3.6/site-packages/airflow/models/taskinstance.py", line 1137, in _run_raw_task
    self._prepare_and_execute_task_with_callbacks(context, task)
  File "/home/airflow/.local/lib/python3.6/site-packages/airflow/models/taskinstance.py", line 1311, in _prepare_and_execute_task_with_callbacks
    result = self._execute_task(context, task_copy)
  File "/home/airflow/.local/lib/python3.6/site-packages/airflow/models/taskinstance.py", line 1341, in _execute_task
    result = task_copy.execute(context=context)
  File "/home/airflow/.local/lib/python3.6/site-packages/airflow/operators/python.py", line 150, in execute
    return_value = self.execute_callable()
  File "/home/airflow/.local/lib/python3.6/site-packages/airflow/operators/python.py", line 161, in execute_callable
    return self.python_callable(*self.op_args, **self.op_kwargs)
  File "/opt/airflow/dags/first_dag.py", line 488, in slot_tracker
    dtype={"slot_hour": TIME()}
  File "/home/airflow/.local/lib/python3.6/site-packages/pandas/core/generic.py", line 2615, in to_sql
    method=method,
  File "/home/airflow/.local/lib/python3.6/site-packages/pandas/io/sql.py", line 598, in to_sql
    method=method,
  File "/home/airflow/.local/lib/python3.6/site-packages/pandas/io/sql.py", line 1406, in to_sql
    raise err
  File "/home/airflow/.local/lib/python3.6/site-packages/pandas/io/sql.py", line 1398, in to_sql
    table.insert(chunksize, method=method)
  File "/home/airflow/.local/lib/python3.6/site-packages/pandas/io/sql.py", line 830, in insert
    exec_insert(conn, keys, chunk_iter)
  File "/home/airflow/.local/lib/python3.6/site-packages/pandas/io/sql.py", line 747, in _execute_insert
    conn.execute(self.table.insert(), data)
  File "/home/airflow/.local/lib/python3.6/site-packages/sqlalchemy/engine/base.py", line 1011, in execute
    return meth(self, multiparams, params)
  File "/home/airflow/.local/lib/python3.6/site-packages/sqlalchemy/sql/elements.py", line 298, in _execute_on_connection
    return connection._execute_clauseelement(self, multiparams, params)
  File "/home/airflow/.local/lib/python3.6/site-packages/sqlalchemy/engine/base.py", line 1130, in _execute_clauseelement
    distilled_params,
  File "/home/airflow/.local/lib/python3.6/site-packages/sqlalchemy/engine/base.py", line 1317, in _execute_context
    e, statement, parameters, cursor, context
  File "/home/airflow/.local/lib/python3.6/site-packages/sqlalchemy/engine/base.py", line 1511, in _handle_dbapi_exception
    sqlalchemy_exception, with_traceback=exc_info[2], from_=e
  File "/home/airflow/.local/lib/python3.6/site-packages/sqlalchemy/util/compat.py", line 182, in raise_
    raise exception
  File "/home/airflow/.local/lib/python3.6/site-packages/sqlalchemy/engine/base.py", line 1257, in _execute_context
    cursor, statement, parameters, context
  File "/home/airflow/.local/lib/python3.6/site-packages/sqlalchemy/dialects/mysql/mysqldb.py", line 148, in do_executemany
    rowcount = cursor.executemany(statement, parameters)
  File "/home/airflow/.local/lib/python3.6/site-packages/MySQLdb/cursors.py", line 236, in executemany
    self._get_db().encoding,
  File "/home/airflow/.local/lib/python3.6/site-packages/MySQLdb/cursors.py", line 261, in _do_execute_many
    rows += self.execute(sql + postfix)
  File "/home/airflow/.local/lib/python3.6/site-packages/MySQLdb/cursors.py", line 206, in execute
    res = self._query(query)
  File "/home/airflow/.local/lib/python3.6/site-packages/MySQLdb/cursors.py", line 319, in _query
    db.query(q)
  File "/home/airflow/.local/lib/python3.6/site-packages/MySQLdb/connections.py", line 259, in query
    _mysql.connection.query(self, query)
sqlalchemy.exc.OperationalError: (MySQLdb._exceptions.OperationalError) (1292, "Incorrect time value: '32400000000000' for column 'slot_hour' at row 1")
[SQL: INSERT INTO `21north`.`21N_slot_tracker` (id, creationdatetime, slot_hour, slot_count, cityid, queuetime, type_of_booking, total_slots, queueid) VALUES (%s, %s, %s, %s, %s, %s, %s, %s, %s)]
[parameters: ((447316, datetime.datetime(2021, 6, 13, 20, 59, 37), 32400000000000, 9, 131, datetime.datetime(2021, 6, 14, 9, 0), 0, 26, 1635088), (447317, datetime.datetime(2021, 6, 13, 21, 53, 23), 32400000000000, 9, 131, datetime.datetime(2021, 6, 14, 9, 0), 0, 27, 1635091), (447318, datetime.datetime(2021, 6, 13, 22, 7, 22), 36000000000000, 6, 53, datetime.datetime(2021, 6, 14, 10, 0), 0, 8, 1635092), (447319, datetime.datetime(2021, 6, 13, 22, 8, 51), 36000000000000, 5, 53, datetime.datetime(2021, 6, 14, 10, 0), 0, 8, 1635093), (447320, datetime.datetime(2021, 6, 13, 22, 15, 4), 28800000000000, 6, 53, datetime.datetime(2021, 6, 14, 8, 0), 0, 8, 1635094), (447321, datetime.datetime(2021, 6, 13, 22, 16, 12), 28800000000000, 5, 53, datetime.datetime(2021, 6, 14, 8, 0), 0, 8, 1635095), (447322, datetime.datetime(2021, 6, 13, 23, 17, 39), 36000000000000, 6, 53, datetime.datetime(2021, 6, 14, 10, 0), 0, 8, 1635097), (447323, datetime.datetime(2021, 6, 13, 23, 21, 56), 36000000000000, 5, 53, datetime.datetime(2021, 6, 14, 10, 0), 0, 8, 1635098)  ... displaying 10 of 926 total bound parameter sets ...  (448240, datetime.datetime(2021, 6, 14, 16, 14, 31), 36000000000000, 53, 148, datetime.datetime(2021, 6, 15, 10, 0), 0, 69, 1636292), (448241, datetime.datetime(2021, 6, 14, 16, 14, 34), 32400000000000, 5, 55, datetime.datetime(2021, 6, 15, 9, 0), 0, 20, 1636293))]
(Background on this error at: http://sqlalche.me/e/13/e3q8)
[2021-06-14 15:29:08,080] {taskinstance.py:1531} INFO - Marking task as UP_FOR_RETRY. dag_id=summary_db, task_id=slot_tracker, execution_date=20210613T000000, start_date=20210614T152836, end_date=20210614T152908
[2021-06-14 15:29:08,170] {local_task_job.py:151} INFO - Task exited with return code 1
[2021-06-14 18:34:41,339] {taskinstance.py:876} INFO - Dependencies all met for <TaskInstance: summary_db.slot_tracker 2021-06-13T00:00:00+00:00 [queued]>
[2021-06-14 18:34:41,712] {taskinstance.py:876} INFO - Dependencies all met for <TaskInstance: summary_db.slot_tracker 2021-06-13T00:00:00+00:00 [queued]>
[2021-06-14 18:34:41,713] {taskinstance.py:1067} INFO - 
--------------------------------------------------------------------------------
[2021-06-14 18:34:41,713] {taskinstance.py:1068} INFO - Starting attempt 1 of 2
[2021-06-14 18:34:41,716] {taskinstance.py:1069} INFO - 
--------------------------------------------------------------------------------
[2021-06-14 18:34:41,783] {taskinstance.py:1087} INFO - Executing <Task(PythonOperator): slot_tracker> on 2021-06-13T00:00:00+00:00
[2021-06-14 18:34:41,810] {standard_task_runner.py:52} INFO - Started process 310 to run task
[2021-06-14 18:34:41,866] {standard_task_runner.py:76} INFO - Running: ['***', 'tasks', 'run', 'summary_db', 'slot_tracker', '2021-06-13T00:00:00+00:00', '--job-id', '127', '--pool', 'default_pool', '--raw', '--subdir', 'DAGS_FOLDER/first_dag.py', '--cfg-path', '/tmp/tmpsu0t1go3', '--error-file', '/tmp/tmpnb17wjb3']
[2021-06-14 18:34:41,867] {standard_task_runner.py:77} INFO - Job 127: Subtask slot_tracker
[2021-06-14 18:34:42,438] {logging_mixin.py:104} INFO - Running <TaskInstance: summary_db.slot_tracker 2021-06-13T00:00:00+00:00 [running]> on host 89c270a4555f
[2021-06-14 18:34:42,946] {taskinstance.py:1282} INFO - Exporting the following env vars:
AIRFLOW_CTX_DAG_OWNER=***
AIRFLOW_CTX_DAG_ID=summary_db
AIRFLOW_CTX_TASK_ID=slot_tracker
AIRFLOW_CTX_EXECUTION_DATE=2021-06-13T00:00:00+00:00
AIRFLOW_CTX_DAG_RUN_ID=scheduled__2021-06-13T00:00:00+00:00
[2021-06-14 18:34:42,949] {logging_mixin.py:104} INFO - ------------------------------------Inside Function-----------------------------
[2021-06-14 18:35:09,723] {logging_mixin.py:104} INFO - -------------------------------Data read into dataframe---------------------------
[2021-06-14 18:35:10,858] {logging_mixin.py:104} WARNING - /home/***/.local/lib/python3.6/site-packages/pandas/io/sql.py:1423 UserWarning: The provided table name '21N_slot_tracker' is not found exactly as such in the database after writing the table, possibly due to case sensitivity issues. Consider using lower case table names.
[2021-06-14 18:35:10,858] {logging_mixin.py:104} INFO - ----------------------------------Data written into summary DB----------------------
[2021-06-14 18:35:10,858] {python.py:151} INFO - Done. Returned value was: None
[2021-06-14 18:35:10,911] {taskinstance.py:1191} INFO - Marking task as SUCCESS. dag_id=summary_db, task_id=slot_tracker, execution_date=20210613T000000, start_date=20210614T183441, end_date=20210614T183510
[2021-06-14 18:35:11,308] {taskinstance.py:1245} INFO - 0 downstream tasks scheduled from follow-on schedule check
[2021-06-14 18:35:11,365] {local_task_job.py:151} INFO - Task exited with return code 0
